Workbook

Sheet Groups
A1: Vehicle Type | D1: WEEK GROUP
A2: Mini Bus | B2: A | D2: WK 1 | E2: WK 3
A3: Mini Truck | B3: B | D3: WK 2 | E3: WK 4
A4: Tricycle | B4: C | D4: WK 5 | E4: WK 7
A5: Van | B5: D | D5: WK 6 | E5: WK 8
D6: WK 9 | E6: WK 11
D7: WK 10 | E7: WK 12
D8: WK 13 | E8: WK 15
D9: WK 14 | E9: WK 16
D10: WK 17 | E10: WK 19
D11: WK 18 | E11: WK 20
D12: WK 21 | E12: WK 23
D13: WK 22 | E13: WK 24
D14: WK 25 | E14: WK 27
D15: WK 26 | E15: WK 28
D16: WK 29 | E16: WK 31
D17: WK 30 | E17: WK 32
... D27: WK 50 | E27: WK 52

Sheet Full Automated Hybrid
A1: START DATE | B1: =TODAY() -> 45065 | C1: TRACKER | D1: OFF | E1: ON | J1: Count of Days Off | K1: =IF(COUNTIF(K$5:K$450,"OFF")=0,"",COUNTIF(K$5:K$450,"OFF")) | L1: =IF(COUNTIF(L$5:L$450,"OFF")=0,"",COUNTIF(L$5:L$450,"OFF")) | M1: =IF(COUNTIF(M$5:M$450,"OFF")=0,"",COUNTIF(M$5:M$450,"OFF")) -> 56 | N1: =IF(COUNTIF(N$5:N$450,"OFF")=0,"",COUNTIF(N$5:N$450,"OFF")) -> 55 | O1: =IF(COUNTIF(O$5:O$450,"OFF")=0,"",COUNTIF(O$5:O$450,"OFF")) -> 56 | P1: =IF(COUNTIF(P$5:P$450,"OFF")=0,"",COUNTIF(P$5:P$450,"OFF")) -> 56 | Q1: =IF(COUNTIF(Q$5:Q$450,"OFF")=0,"",COUNTIF(Q$5:Q$450,"OFF")) | R1: =IF(COUNTIF(R$5:R$450,"OFF")=0,"",COUNTIF(R$5:R$450,"OFF")) | ... AO1: =IF(COUNTIF(AO$5:AO$450,"OFF")=0,"",COUNTIF(AO$5:AO$450,"OFF"))
A2: CURRENT TIME | B2: =NOW() -> 45065.578 | K2: 45047 | L2: 45048 | M2: 45049 | N2: 45050 | O2: 45051 | P2: 45052 | Q2: 45053 | R2: 45054 | S2: 45055 | T2: 45056 | U2: 45057 | V2: 45058 | W2: 45059 | X2: 45060 | Y2: 45061 | Z2: 45062 | AA2: 45063 | AB2: 45064 | AC2: 45065 | AD2: 45066 | AE2: 45067 | AF2: 45068 | AG2: 45069 | AH2: 45070 | AI2: 45071 | AJ2: 45072 | AK2: 45073 | AL2: 45074 | AM2: 45075 | AN2: 45076 | AO2: 45077
K3: ="Week "&_xlfn.ISOWEEKNUM($K$2) -> Week 18 | R3: ="Week "&_xlfn.ISOWEEKNUM($R$2) -> Week 19 | Y3: ="Week "&_xlfn.ISOWEEKNUM($Y$2) -> Week 20 | AF3: ="Week "&_xlfn.ISOWEEKNUM($AF$2) -> Week 21 | AM3: ="Week "&_xlfn.ISOWEEKNUM($AM$2) -> Week 22
A4: Warehouse | B4: Fleet Operator Name | C4: Vehicle Plate | D4: Vehicle Type | E4: WorkDay | F4: Day-Off | G4: Days Group | H4: Vehicle Type Group | I4: Week Group | K4: =TEXT(K2,"DDD") -> Mon | L4: =TEXT(L2,"DDD") -> Tue | M4: =TEXT(M2,"DDD") -> Wed | N4: =TEXT(N2,"DDD") -> Thu | O4: =TEXT(O2,"DDD") -> Fri | P4: =TEXT(P2,"DDD") -> Sat | Q4: =TEXT(Q2,"DDD") -> Sun | R4: =TEXT(R2,"DDD") -> Mon | ... AO4: =TEXT(AO2,"DDD") -> Wed
A5: =CHOOSE(RANDBETWEEN(1,5),"Lagos","Ogun","Ondo","Oyo","Ekiti") -> Ogun | B5: =CHOOSE(RANDBETWEEN(1,5),"A","B","C","D","E") -> E | C5: =CHOOSE(RANDBETWEEN(1,5),"A1","B1","C1","D1","E1") -> D1 | D5: Mini Bus | E5: =COUNTIF(K5:AO5, "ON") -> 25 | F5: =COUNTIF(K5:AO5, "OFF") -> 2 | G5: {=Groups!$B$2:$B$5} -> A | H5: {=Groups!$B$2:$B$5} -> A | I5: =IF($A5="","",IF(COUNTA($K$2:$P$2)=6,"WK "&_xlfn.ISOWEEKNUM($K$2))) -> WK 18 | J5: =IF($A5="","",IF(COUNTA($Y$2:$AD$2)=6,"WK "&_xlfn.ISOWEEKNUM($Y$2))) -> WK 20 | K5: =IF($A5="","",IF(COUNTA($K$2:$AO$2)-4,IF(OR(K$4="Mon",K$4="Tue"),$E$1,$D$1))) -> ON | L5: =IF($A5="","",IF(COUNTA($K$2:$AO$2)-4,IF(OR(L$4="Mon",L$4="Tue"),$E$1,$D$1))) -> ON | M5: =IF($A5="","",IF(COUNTA($K$2:$AO$2)-4,IF(OR(M$4<>"Mon",M$4<>"Tue"),IF(AND($G5="A",$H5="A",$I5="WK "&_xlfn.ISOWEEKNUM($K$2)),$D$1,$E$1)))) -> OFF | N5: =IF($A5="","",IF(COUNTA($K$2:$AO$2)-4,IF(OR(N$4<>"Mon",N$4<>"Tue"),IF(AND($G5="B",$H5="B",$I5="WK "&_xlfn.ISOWEEKNUM($K$2)),$D$1,$E$1)))) -> ON | O5: =IF($A5="","",IF(COUNTA($K$2:$AO$2)-4,IF(OR(O$4<>"Mon",O$4<>"Tue"),IF(AND($G5="C",$H5="C",$I5="WK "&_xlfn.ISOWEEKNUM($K$2)),$D$1,$E$1)))) -> ON | P5: =IF($A5="","",IF(COUNTA($K$2:$AO$2)-4,IF(OR(P$4<>"Mon",P$4<>"Tue"),IF(AND($G5="D",$H5="D",$I5="WK "&_xlfn.ISOWEEKNUM($K$2)),$D$1,$E$1)))) -> ON | R5: =IF($A5="","",IF(COUNTA($K$2:$AO$2)-4,IF(OR(R$4="Mon",R$4="Tue"),$E$1,$D$1))) -> ON | S5: =IF($A5="","",IF(COUNTA($K$2:$AO$2)-4,IF(OR(S$4="Mon",S$4="Tue"),$E$1,$D$1))) -> ON | T5: =IF($A5="","",IF(COUNTA($K$2:$AO$2)-4,IF(OR(T$4<>"Mon",T$4<>"Tue"),IF(AND($G5="A",$H5="A",$I5="WK "&_xlfn.ISOWEEKNUM($R$2)),$D$1,$E$1)))) -> ON | U5: =IF($A5="","",IF(COUNTA($K$2:$AO$2)-4,IF(OR(U$4<>"Mon",U$4<>"Tue"),IF(AND($G5="B",$H5="B",$I5="WK "&_xlfn.ISOWEEKNUM($R$2)),$D$1,$E$1)))) -> ON | V5: =IF($A5="","",IF(COUNTA($K$2:$AO$2)-4,IF(OR(V$4<>"Mon",V$4<>"Tue"),IF(AND($G5="C",$H5="C",$I5="WK "&_xlfn.ISOWEEKNUM($R$2)),$D$1,$E$1)))) -> ON | W5: =IF($A5="","",IF(COUNTA($K$2:$AO$2)-4,IF(OR(W$4<>"Mon",W$4<>"Tue"),IF(AND($G5="D",$H5="D",$I5="WK "&_xlfn.ISOWEEKNUM($R$2)),$D$1,$E$1)))) -> ON | Y5: =IF($A5="","",IF(COUNTA($K$2:$AO$2)-4,IF(OR(Y$4="Mon",Y$4="Tue"),$E$1,$D$1))) -> ON | Z5: =IF($A5="","",IF(COUNTA($K$2:$AO$2)-4,IF(OR(Z$4="Mon",Z$4="Tue"),$E$1,$D$1))) -> ON | AA5: =IF($A5="","",IF(COUNTA($K$2:$AO$2)-4,IF(OR(AA$4<>"Mon",AA$4<>"Tue"),IF(AND($G5="A",$H5="A",$J5="WK "&_xlfn.ISOWEEKNUM($Y$2)),$D$1,$E$1)))) -> OFF | AB5: =IF($A5="","",IF(COUNTA($K$2:$AO$2)-4,IF(OR(AB$4<>"Mon",AB$4<>"Tue"),IF(AND($G5="B",$H5="B",$J5="WK "&_xlfn.ISOWEEKNUM($Y$2)),$D$1,$E$1)))) -> ON | AC5: =IF($A5="","",IF(COUNTA($K$2:$AO$2)-4,IF(OR(AC$4<>"Mon",AC$4<>"Tue"),IF(AND($G5="C",$H5="C",$J5="WK "&_xlfn.ISOWEEKNUM($Y$2)),$D$1,$E$1)))) -> ON | AD5: =IF($A5="","",IF(COUNTA($K$2:$AO$2)-4,IF(OR(AD$4<>"Mon",AD$4<>"Tue"),IF(AND($G5="D",$H5="D",$J5="WK "&_xlfn.ISOWEEKNUM($Y$2)),$D$1,$E$1)))) -> ON | AF5: =IF($A5="","",IF(COUNTA($K$2:$AO$2)-4,IF(OR(AF$4="Mon",AF$4="Tue"),$E$1,$D$1))) -> ON | AG5: =IF($A5="","",IF(COUNTA($K$2:$AO$2)-4,IF(OR(AG$4="Mon",AG$4="Tue"),$E$1,$D$1))) -> ON | AH5: =IF($A5="","",IF(COUNTA($K$2:$AO$2)-4,IF(OR(AH$4<>"Mon",AH$4<>"Tue"),IF(AND($G5="A",$H5="A",$J5="WK "&_xlfn.ISOWEEKNUM($AF$2)),$D$1,$E$1)))) -> ON | AI5: =IF($A5="","",IF(COUNTA($K$2:$AO$2)-4,IF(OR(AI$4<>"Mon",AI$4<>"Tue"),IF(AND($G5="B",$H5="B",$J5="WK "&_xlfn.ISOWEEKNUM($AF$2)),$D$1,$E$1)))) -> ON | AJ5: =IF($A5="","",IF(COUNTA($K$2:$AO$2)-4,IF(OR(AJ$4<>"Mon",AJ$4<>"Tue"),IF(AND($G5="C",$H5="C",$J5="WK "&_xlfn.ISOWEEKNUM($AF$2)),$D$1,$E$1)))) -> ON | AK5: =IF($A5="","",IF(COUNTA($K$2:$AO$2)-4,IF(OR(AK$4<>"Mon",AK$4<>"Tue"),IF(AND($G5="D",$H5="D",$J5="WK "&_xlfn.ISOWEEKNUM($AF$2)),$D$1,$E$1)))) -> ON | AM5: =IF(COUNTA($K$2:$AO$2)-4,IF(OR(AM$4="Mon",AM$4="Tue"),$E$1,$D$1)) -> ON | AN5: =IF(COUNTA($K$2:$AO$2)-4,IF(OR(AN$4="Mon",AN$4="Tue"),$E$1,$D$1)) -> ON | AO5: =IF(COUNTA($K$2:$AO$2)-4,IF(OR(AO$4="Mon",AO$4="Tue",AO$4="Wed"),$E$1,$D$1)) -> ON
A6: =CHOOSE(RANDBETWEEN(1,5),"Lagos","Ogun","Ondo","Oyo","Ekiti") -> Ogun | B6: =CHOOSE(RANDBETWEEN(1,5),"A","B","C","D","E") -> E | C6: =CHOOSE(RANDBETWEEN(1,5),"A1","B1","C1","D1","E1") -> D1 | D6: Mini Bus | E6: =COUNTIF(K6:AO6, "ON") -> 25 | F6: =COUNTIF(K6:AO6, "OFF") -> 2 | G6: B | H6: B | I6: =IF($A6="","",IF(COUNTA($R$2:$W$2)=6,"WK "&_xlfn.ISOWEEKNUM($R$2))) -> WK 19 | J6: =IF($A6="","",IF(COUNTA($AF$2:$AK$2)=6,"WK "&_xlfn.ISOWEEKNUM($AF$2))) -> WK 21 | K6: =IF($A6="","",IF(COUNTA($K$2:$AO$2)-4,IF(OR(K$4="Mon",K$4="Tue"),$E$1,$D$1))) -> ON | L6: =IF($A6="","",IF(COUNTA($K$2:$AO$2)-4,IF(OR(L$4="Mon",L$4="Tue"),$E$1,$D$1))) -> ON | M6: =IF($A6="","",IF(COUNTA($K$2:$AO$2)-4,IF(OR(M$4<>"Mon",M$4<>"Tue"),IF(AND($G6="A",$H6="A",$I6="WK "&_xlfn.ISOWEEKNUM($K$2)),$D$1,$E$1)))) -> ON | N6: =IF($A6="","",IF(COUNTA($K$2:$AO$2)-4,IF(OR(N$4<>"Mon",N$4<>"Tue"),IF(AND($G6="B",$H6="B",$I6="WK "&_xlfn.ISOWEEKNUM($K$2)),$D$1,$E$1)))) -> ON | O6: =IF($A6="","",IF(COUNTA($K$2:$AO$2)-4,IF(OR(O$4<>"Mon",O$4<>"Tue"),IF(AND($G6="C",$H6="C",$I6="WK "&_xlfn.ISOWEEKNUM($K$2)),$D$1,$E$1)))) -> ON | P6: =IF($A6="","",IF(COUNTA($K$2:$AO$2)-4,IF(OR(P$4<>"Mon",P$4<>"Tue"),IF(AND($G6="D",$H6="D",$I6="WK "&_xlfn.ISOWEEKNUM($K$2)),$D$1,$E$1)))) -> ON | R6: =IF($A6="","",IF(COUNTA($K$2:$AO$2)-4,IF(OR(R$4="Mon",R$4="Tue"),$E$1,$D$1))) -> ON | S6: =IF($A6="","",IF(COUNTA($K$2:$AO$2)-4,IF(OR(S$4="Mon",S$4="Tue"),$E$1,$D$1))) -> ON | T6: =IF($A6="","",IF(COUNTA($K$2:$AO$2)-4,IF(OR(T$4<>"Mon",T$4<>"Tue"),IF(AND($G6="A",$H6="A",$I6="WK "&_xlfn.ISOWEEKNUM($R$2)),$D$1,$E$1)))) -> ON | U6: =IF($A6="","",IF(COUNTA($K$2:$AO$2)-4,IF(OR(U$4<>"Mon",U$4<>"Tue"),IF(AND($G6="B",$H6="B",$I6="WK "&_xlfn.ISOWEEKNUM($R$2)),$D$1,$E$1)))) -> OFF | V6: =IF($A6="","",IF(COUNTA($K$2:$AO$2)-4,IF(OR(V$4<>"Mon",V$4<>"Tue"),IF(AND($G6="C",$H6="C",$I6="WK "&_xlfn.ISOWEEKNUM($R$2)),$D$1,$E$1)))) -> ON | W6: =IF($A6="","",IF(COUNTA($K$2:$AO$2)-4,IF(OR(W$4<>"Mon",W$4<>"Tue"),IF(AND($G6="D",$H6="D",$I6="WK "&_xlfn.ISOWEEKNUM($R$2)),$D$1,$E$1)))) -> ON | Y6: =IF($A6="","",IF(COUNTA($K$2:$AO$2)-4,IF(OR(Y$4="Mon",Y$4="Tue"),$E$1,$D$1))) -> ON | Z6: =IF($A6="","",IF(COUNTA($K$2:$AO$2)-4,IF(OR(Z$4="Mon",Z$4="Tue"),$E$1,$D$1))) -> ON | AA6: =IF($A6="","",IF(COUNTA($K$2:$AO$2)-4,IF(OR(AA$4<>"Mon",AA$4<>"Tue"),IF(AND($G6="A",$H6="A",$J6="WK "&_xlfn.ISOWEEKNUM($Y$2)),$D$1,$E$1)))) -> ON | AB6: =IF($A6="","",IF(COUNTA($K$2:$AO$2)-4,IF(OR(AB$4<>"Mon",AB$4<>"Tue"),IF(AND($G6="B",$H6="B",$J6="WK "&_xlfn.ISOWEEKNUM($Y$2)),$D$1,$E$1)))) -> ON | AC6: =IF($A6="","",IF(COUNTA($K$2:$AO$2)-4,IF(OR(AC$4<>"Mon",AC$4<>"Tue"),IF(AND($G6="C",$H6="C",$J6="WK "&_xlfn.ISOWEEKNUM($Y$2)),$D$1,$E$1)))) -> ON | AD6: =IF($A6="","",IF(COUNTA($K$2:$AO$2)-4,IF(OR(AD$4<>"Mon",AD$4<>"Tue"),IF(AND($G6="D",$H6="D",$J6="WK "&_xlfn.ISOWEEKNUM($Y$2)),$D$1,$E$1)))) -> ON | AF6: =IF($A6="","",IF(COUNTA($K$2:$AO$2)-4,IF(OR(AF$4="Mon",AF$4="Tue"),$E$1,$D$1))) -> ON | AG6: =IF($A6="","",IF(COUNTA($K$2:$AO$2)-4,IF(OR(AG$4="Mon",AG$4="Tue"),$E$1,$D$1))) -> ON | AH6: =IF($A6="","",IF(COUNTA($K$2:$AO$2)-4,IF(OR(AH$4<>"Mon",AH$4<>"Tue"),IF(AND($G6="A",$H6="A",$J6="WK "&_xlfn.ISOWEEKNUM($AF$2)),$D$1,$E$1)))) -> ON | AI6: =IF($A6="","",IF(COUNTA($K$2:$AO$2)-4,IF(OR(AI$4<>"Mon",AI$4<>"Tue"),IF(AND($G6="B",$H6="B",$J6="WK "&_xlfn.ISOWEEKNUM($AF$2)),$D$1,$E$1)))) -> OFF | AJ6: =IF($A6="","",IF(COUNTA($K$2:$AO$2)-4,IF(OR(AJ$4<>"Mon",AJ$4<>"Tue"),IF(AND($G6="C",$H6="C",$J6="WK "&_xlfn.ISOWEEKNUM($AF$2)),$D$1,$E$1)))) -> ON | AK6: =IF($A6="","",IF(COUNTA($K$2:$AO$2)-4,IF(OR(AK$4<>"Mon",AK$4<>"Tue"),IF(AND($G6="D",$H6="D",$J6="WK "&_xlfn.ISOWEEKNUM($AF$2)),$D$1,$E$1)))) -> ON | AM6: =IF(COUNTA($K$2:$AO$2)-4,IF(OR(AM$4="Mon",AM$4="Tue"),$E$1,$D$1)) -> ON | AN6: =IF(COUNTA($K$2:$AO$2)-4,IF(OR(AN$4="Mon",AN$4="Tue"),$E$1,$D$1)) -> ON | AO6: =IF(COUNTA($K$2:$AO$2)-4,IF(OR(AO$4="Mon",AO$4="Tue",AO$4="Wed"),$E$1,$D$1)) -> ON
A7: =CHOOSE(RANDBETWEEN(1,5),"Lagos","Ogun","Ondo","Oyo","Ekiti") -> Ekiti | B7: =CHOOSE(RANDBETWEEN(1,5),"A","B","C","D","E") -> A | C7: =CHOOSE(RANDBETWEEN(1,5),"A1","B1","C1","D1","E1") -> C1 | D7: Mini Bus | E7: =COUNTIF(K7:AO7, "ON") -> 25 | F7: =COUNTIF(K7:AO7, "OFF") -> 2 | G7: C | H7: C | I7: =IF($A7="","",IF(COUNTA($K$2:$P$2)=6,"WK "&_xlfn.ISOWEEKNUM($K$2))) -> WK 18 | J7: =IF($A7="","",IF(COUNTA($Y$2:$AD$2)=6,"WK "&_xlfn.ISOWEEKNUM($Y$2))) -> WK 20 | K7: =IF($A7="","",IF(COUNTA($K$2:$AO$2)-4,IF(OR(K$4="Mon",K$4="Tue"),$E$1,$D$1))) -> ON | L7: =IF($A7="","",IF(COUNTA($K$2:$AO$2)-4,IF(OR(L$4="Mon",L$4="Tue"),$E$1,$D$1))) -> ON | M7: =IF($A7="","",IF(COUNTA($K$2:$AO$2)-4,IF(OR(M$4<>"Mon",M$4<>"Tue"),IF(AND($G7="A",$H7="A",$I7="WK "&_xlfn.ISOWEEKNUM($K$2)),$D$1,$E$1)))) -> ON | N7: =IF($A7="","",IF(COUNTA($K$2:$AO$2)-4,IF(OR(N$4<>"Mon",N$4<>"Tue"),IF(AND($G7="B",$H7="B",$I7="WK "&_xlfn.ISOWEEKNUM($K$2)),$D$1,$E$1)))) -> ON | O7: =IF($A7="","",IF(COUNTA($K$2:$AO$2)-4,IF(OR(O$4<>"Mon",O$4<>"Tue"),IF(AND($G7="C",$H7="C",$I7="WK "&_xlfn.ISOWEEKNUM($K$2)),$D$1,$E$1)))) -> OFF | P7: =IF($A7="","",IF(COUNTA($K$2:$AO$2)-4,IF(OR(P$4<>"Mon",P$4<>"Tue"),IF(AND($G7="D",$H7="D",$I7="WK "&_xlfn.ISOWEEKNUM($K$2)),$D$1,$E$1)))) -> ON | R7: =IF($A7="","",IF(COUNTA($K$2:$AO$2)-4,IF(OR(R$4="Mon",R$4="Tue"),$E$1,$D$1))) -> ON | S7: =IF($A7="","",IF(COUNTA($K$2:$AO$2)-4,IF(OR(S$4="Mon",S$4="Tue"),$E$1,$D$1))) -> ON | T7: =IF($A7="","",IF(COUNTA($K$2:$AO$2)-4,IF(OR(T$4<>"Mon",T$4<>"Tue"),IF(AND($G7="A",$H7="A",$I7="WK "&_xlfn.ISOWEEKNUM($R$2)),$D$1,$E$1)))) -> ON | U7: =IF($A7="","",IF(COUNTA($K$2:$AO$2)-4,IF(OR(U$4<>"Mon",U$4<>"Tue"),IF(AND($G7="B",$H7="B",$I7="WK "&_xlfn.ISOWEEKNUM($R$2)),$D$1,$E$1)))) -> ON | V7: =IF($A7="","",IF(COUNTA($K$2:$AO$2)-4,IF(OR(V$4<>"Mon",V$4<>"Tue"),IF(AND($G7="C",$H7="C",$I7="WK "&_xlfn.ISOWEEKNUM($R$2)),$D$1,$E$1)))) -> ON | W7: =IF($A7="","",IF(COUNTA($K$2:$AO$2)-4,IF(OR(W$4<>"Mon",W$4<>"Tue"),IF(AND($G7="D",$H7="D",$I7="WK "&_xlfn.ISOWEEKNUM($R$2)),$D$1,$E$1)))) -> ON | Y7: =IF($A7="","",IF(COUNTA($K$2:$AO$2)-4,IF(OR(Y$4="Mon",Y$4="Tue"),$E$1,$D$1))) -> ON | Z7: =IF($A7="","",IF(COUNTA($K$2:$AO$2)-4,IF(OR(Z$4="Mon",Z$4="Tue"),$E$1,$D$1))) -> ON | AA7: =IF($A7="","",IF(COUNTA($K$2:$AO$2)-4,IF(OR(AA$4<>"Mon",AA$4<>"Tue"),IF(AND($G7="A",$H7="A",$J7="WK "&_xlfn.ISOWEEKNUM($Y$2)),$D$1,$E$1)))) -> ON | AB7: =IF($A7="","",IF(COUNTA($K$2:$AO$2)-4,IF(OR(AB$4<>"Mon",AB$4<>"Tue"),IF(AND($G7="B",$H7="B",$J7="WK "&_xlfn.ISOWEEKNUM($Y$2)),$D$1,$E$1)))) -> ON | AC7: =IF($A7="","",IF(COUNTA($K$2:$AO$2)-4,IF(OR(AC$4<>"Mon",AC$4<>"Tue"),IF(AND($G7="C",$H7="C",$J7="WK "&_xlfn.ISOWEEKNUM($Y$2)),$D$1,$E$1)))) -> OFF | AD7: =IF($A7="","",IF(COUNTA($K$2:$AO$2)-4,IF(OR(AD$4<>"Mon",AD$4<>"Tue"),IF(AND($G7="D",$H7="D",$J7="WK "&_xlfn.ISOWEEKNUM($Y$2)),$D$1,$E$1)))) -> ON | AF7: =IF($A7="","",IF(COUNTA($K$2:$AO$2)-4,IF(OR(AF$4="Mon",AF$4="Tue"),$E$1,$D$1))) -> ON | AG7: =IF($A7="","",IF(COUNTA($K$2:$AO$2)-4,IF(OR(AG$4="Mon",AG$4="Tue"),$E$1,$D$1))) -> ON | AH7: =IF($A7="","",IF(COUNTA($K$2:$AO$2)-4,IF(OR(AH$4<>"Mon",AH$4<>"Tue"),IF(AND($G7="A",$H7="A",$J7="WK "&_xlfn.ISOWEEKNUM($AF$2)),$D$1,$E$1)))) -> ON | AI7: =IF($A7="","",IF(COUNTA($K$2:$AO$2)-4,IF(OR(AI$4<>"Mon",AI$4<>"Tue"),IF(AND($G7="B",$H7="B",$J7="WK "&_xlfn.ISOWEEKNUM($AF$2)),$D$1,$E$1)))) -> ON | AJ7: =IF($A7="","",IF(COUNTA($K$2:$AO$2)-4,IF(OR(AJ$4<>"Mon",AJ$4<>"Tue"),IF(AND($G7="C",$H7="C",$J7="WK "&_xlfn.ISOWEEKNUM($AF$2)),$D$1,$E$1)))) -> ON | AK7: =IF($A7="","",IF(COUNTA($K$2:$AO$2)-4,IF(OR(AK$4<>"Mon",AK$4<>"Tue"),IF(AND($G7="D",$H7="D",$J7="WK "&_xlfn.ISOWEEKNUM($AF$2)),$D$1,$E$1)))) -> ON | AM7: =IF(COUNTA($K$2:$AO$2)-4,IF(OR(AM$4="Mon",AM$4="Tue"),$E$1,$D$1)) -> ON | AN7: =IF(COUNTA($K$2:$AO$2)-4,IF(OR(AN$4="Mon",AN$4="Tue"),$E$1,$D$1)) -> ON | AO7: =IF(COUNTA($K$2:$AO$2)-4,IF(OR(AO$4="Mon",AO$4="Tue",AO$4="Wed"),$E$1,$D$1)) -> ON
A8: =CHOOSE(RANDBETWEEN(1,5),"Lagos","Ogun","Ondo","Oyo","Ekiti") -> Lagos | B8: =CHOOSE(RANDBETWEEN(1,5),"A","B","C","D","E") -> D | C8: =CHOOSE(RANDBETWEEN(1,5),"A1","B1","C1","D1","E1") -> A1 | D8: Mini Bus | E8: =COUNTIF(K8:AO8, "ON") -> 25 | F8: =COUNTIF(K8:AO8, "OFF") -> 2 | G8: D | H8: D | I8: =IF($A8="","",IF(COUNTA($R$2:$W$2)=6,"WK "&_xlfn.ISOWEEKNUM($R$2))) -> WK 19 | J8: =IF($A8="","",IF(COUNTA($AF$2:$AK$2)=6,"WK "&_xlfn.ISOWEEKNUM($AF$2))) -> WK 21 | K8: =IF($A8="","",IF(COUNTA($K$2:$AO$2)-4,IF(OR(K$4="Mon",K$4="Tue"),$E$1,$D$1))) -> ON | L8: =IF($A8="","",IF(COUNTA($K$2:$AO$2)-4,IF(OR(L$4="Mon",L$4="Tue"),$E$1,$D$1))) -> ON | M8: =IF($A8="","",IF(COUNTA($K$2:$AO$2)-4,IF(OR(M$4<>"Mon",M$4<>"Tue"),IF(AND($G8="A",$H8="A",$I8="WK "&_xlfn.ISOWEEKNUM($K$2)),$D$1,$E$1)))) -> ON | N8: =IF($A8="","",IF(COUNTA($K$2:$AO$2)-4,IF(OR(N$4<>"Mon",N$4<>"Tue"),IF(AND($G8="B",$H8="B",$I8="WK "&_xlfn.ISOWEEKNUM($K$2)),$D$1,$E$1)))) -> ON | O8: =IF($A8="","",IF(COUNTA($K$2:$AO$2)-4,IF(OR(O$4<>"Mon",O$4<>"Tue"),IF(AND($G8="C",$H8="C",$I8="WK "&_xlfn.ISOWEEKNUM($K$2)),$D$1,$E$1)))) -> ON | P8: =IF($A8="","",IF(COUNTA($K$2:$AO$2)-4,IF(OR(P$4<>"Mon",P$4<>"Tue"),IF(AND($G8="D",$H8="D",$I8="WK "&_xlfn.ISOWEEKNUM($K$2)),$D$1,$E$1)))) -> ON | R8: =IF($A8="","",IF(COUNTA($K$2:$AO$2)-4,IF(OR(R$4="Mon",R$4="Tue"),$E$1,$D$1))) -> ON | S8: =IF($A8="","",IF(COUNTA($K$2:$AO$2)-4,IF(OR(S$4="Mon",S$4="Tue"),$E$1,$D$1))) -> ON | T8: =IF($A8="","",IF(COUNTA($K$2:$AO$2)-4,IF(OR(T$4<>"Mon",T$4<>"Tue"),IF(AND($G8="A",$H8="A",$I8="WK "&_xlfn.ISOWEEKNUM($R$2)),$D$1,$E$1)))) -> ON | U8: =IF($A8="","",IF(COUNTA($K$2:$AO$2)-4,IF(OR(U$4<>"Mon",U$4<>"Tue"),IF(AND($G8="B",$H8="B",$I8="WK "&_xlfn.ISOWEEKNUM($R$2)),$D$1,$E$1)))) -> ON | V8: =IF($A8="","",IF(COUNTA($K$2:$AO$2)-4,IF(OR(V$4<>"Mon",V$4<>"Tue"),IF(AND($G8="C",$H8="C",$I8="WK "&_xlfn.ISOWEEKNUM($R$2)),$D$1,$E$1)))) -> ON | W8: =IF($A8="","",IF(COUNTA($K$2:$AO$2)-4,IF(OR(W$4<>"Mon",W$4<>"Tue"),IF(AND($G8="D",$H8="D",$I8="WK "&_xlfn.ISOWEEKNUM($R$2)),$D$1,$E$1)))) -> OFF | Y8: =IF($A8="","",IF(COUNTA($K$2:$AO$2)-4,IF(OR(Y$4="Mon",Y$4="Tue"),$E$1,$D$1))) -> ON | Z8: =IF($A8="","",IF(COUNTA($K$2:$AO$2)-4,IF(OR(Z$4="Mon",Z$4="Tue"),$E$1,$D$1))) -> ON | AA8: =IF($A8="","",IF(COUNTA($K$2:$AO$2)-4,IF(OR(AA$4<>"Mon",AA$4<>"Tue"),IF(AND($G8="A",$H8="A",$J8="WK "&_xlfn.ISOWEEKNUM($Y$2)),$D$1,$E$1)))) -> ON | AB8: =IF($A8="","",IF(COUNTA($K$2:$AO$2)-4,IF(OR(AB$4<>"Mon",AB$4<>"Tue"),IF(AND($G8="B",$H8="B",$J8="WK "&_xlfn.ISOWEEKNUM($Y$2)),$D$1,$E$1)))) -> ON | AC8: =IF($A8="","",IF(COUNTA($K$2:$AO$2)-4,IF(OR(AC$4<>"Mon",AC$4<>"Tue"),IF(AND($G8="C",$H8="C",$J8="WK "&_xlfn.ISOWEEKNUM($Y$2)),$D$1,$E$1)))) -> ON | AD8: =IF($A8="","",IF(COUNTA($K$2:$AO$2)-4,IF(OR(AD$4<>"Mon",AD$4<>"Tue"),IF(AND($G8="D",$H8="D",$J8="WK "&_xlfn.ISOWEEKNUM($Y$2)),$D$1,$E$1)))) -> ON | AF8: =IF($A8="","",IF(COUNTA($K$2:$AO$2)-4,IF(OR(AF$4="Mon",AF$4="Tue"),$E$1,$D$1))) -> ON | AG8: =IF($A8="","",IF(COUNTA($K$2:$AO$2)-4,IF(OR(AG$4="Mon",AG$4="Tue"),$E$1,$D$1))) -> ON | AH8: =IF($A8="","",IF(COUNTA($K$2:$AO$2)-4,IF(OR(AH$4<>"Mon",AH$4<>"Tue"),IF(AND($G8="A",$H8="A",$J8="WK "&_xlfn.ISOWEEKNUM($AF$2)),$D$1,$E$1)))) -> ON | AI8: =IF($A8="","",IF(COUNTA($K$2:$AO$2)-4,IF(OR(AI$4<>"Mon",AI$4<>"Tue"),IF(AND($G8="B",$H8="B",$J8="WK "&_xlfn.ISOWEEKNUM($AF$2)),$D$1,$E$1)))) -> ON | AJ8: =IF($A8="","",IF(COUNTA($K$2:$AO$2)-4,IF(OR(AJ$4<>"Mon",AJ$4<>"Tue"),IF(AND($G8="C",$H8="C",$J8="WK "&_xlfn.ISOWEEKNUM($AF$2)),$D$1,$E$1)))) -> ON | AK8: =IF($A8="","",IF(COUNTA($K$2:$AO$2)-4,IF(OR(AK$4<>"Mon",AK$4<>"Tue"),IF(AND($G8="D",$H8="D",$J8="WK "&_xlfn.ISOWEEKNUM($AF$2)),$D$1,$E$1)))) -> OFF | AM8: =IF(COUNTA($K$2:$AO$2)-4,IF(OR(AM$4="Mon",AM$4="Tue"),$E$1,$D$1)) -> ON | AN8: =IF(COUNTA($K$2:$AO$2)-4,IF(OR(AN$4="Mon",AN$4="Tue"),$E$1,$D$1)) -> ON | AO8: =IF(COUNTA($K$2:$AO$2)-4,IF(OR(AO$4="Mon",AO$4="Tue",AO$4="Wed"),$E$1,$D$1)) -> ON
A9: =CHOOSE(RANDBETWEEN(1,5),"Lagos","Ogun","Ondo","Oyo","Ekiti") -> Lagos | B9: =CHOOSE(RANDBETWEEN(1,5),"A","B","C","D","E") -> C | C9: =CHOOSE(RANDBETWEEN(1,5),"A1","B1","C1","D1","E1") -> A1 | D9: Mini Bus | E9: =COUNTIF(K9:AO9, "ON") -> 25 | F9: =COUNTIF(K9:AO9, "OFF") -> 2 | G9: {=IF($G$5:$G$8={"A";"B";"C";"D"},{"D";"C";"B";"A"},{"A";"B";"C";"D"})} -> D | H9: {=IF($H$5:$H$8={"A";"B";"C";"D"},{"D";"C";"B";"A"},{"A";"B";"C";"D"})} -> D | I9: =IF($A9="","",IF(COUNTA($K$2:$P$2)=6,"WK "&_xlfn.ISOWEEKNUM($K$2))) -> WK 18 | J9: =IF($A9="","",IF(COUNTA($Y$2:$AD$2)=6,"WK "&_xlfn.ISOWEEKNUM($Y$2))) -> WK 20 | K9: =IF($A9="","",IF(COUNTA($K$2:$AO$2)-4,IF(OR(K$4="Mon",K$4="Tue"),$E$1,$D$1))) -> ON | L9: =IF($A9="","",IF(COUNTA($K$2:$AO$2)-4,IF(OR(L$4="Mon",L$4="Tue"),$E$1,$D$1))) -> ON | M9: =IF($A9="","",IF(COUNTA($K$2:$AO$2)-4,IF(OR(M$4<>"Mon",M$4<>"Tue"),IF(AND($G9="A",$H9="A",$I9="WK "&_xlfn.ISOWEEKNUM($K$2)),$D$1,$E$1)))) -> ON | N9: =IF($A9="","",IF(COUNTA($K$2:$AO$2)-4,IF(OR(N$4<>"Mon",N$4<>"Tue"),IF(AND($G9="B",$H9="B",$I9="WK "&_xlfn.ISOWEEKNUM($K$2)),$D$1,$E$1)))) -> ON | O9: =IF($A9="","",IF(COUNTA($K$2:$AO$2)-4,IF(OR(O$4<>"Mon",O$4<>"Tue"),IF(AND($G9="C",$H9="C",$I9="WK "&_xlfn.ISOWEEKNUM($K$2)),$D$1,$E$1)))) -> ON | P9: =IF($A9="","",IF(COUNTA($K$2:$AO$2)-4,IF(OR(P$4<>"Mon",P$4<>"Tue"),IF(AND($G9="D",$H9="D",$I9="WK "&_xlfn.ISOWEEKNUM($K$2)),$D$1,$E$1)))) -> OFF | R9: =IF($A9="","",IF(COUNTA($K$2:$AO$2)-4,IF(OR(R$4="Mon",R$4="Tue"),$E$1,$D$1))) -> ON | S9: =IF($A9="","",IF(COUNTA($K$2:$AO$2)-4,IF(OR(S$4="Mon",S$4="Tue"),$E$1,$D$1))) -> ON | T9: =IF($A9="","",IF(COUNTA($K$2:$AO$2)-4,IF(OR(T$4<>"Mon",T$4<>"Tue"),IF(AND($G9="A",$H9="A",$I9="WK "&_xlfn.ISOWEEKNUM($R$2)),$D$1,$E$1)))) -> ON | U9: =IF($A9="","",IF(COUNTA($K$2:$AO$2)-4,IF(OR(U$4<>"Mon",U$4<>"Tue"),IF(AND($G9="B",$H9="B",$I9="WK "&_xlfn.ISOWEEKNUM($R$2)),$D$1,$E$1)))) -> ON | V9: =IF($A9="","",IF(COUNTA($K$2:$AO$2)-4,IF(OR(V$4<>"Mon",V$4<>"Tue"),IF(AND($G9="C",$H9="C",$I9="WK "&_xlfn.ISOWEEKNUM($R$2)),$D$1,$E$1)))) -> ON | W9: =IF($A9="","",IF(COUNTA($K$2:$AO$2)-4,IF(OR(W$4<>"Mon",W$4<>"Tue"),IF(AND($G9="D",$H9="D",$I9="WK "&_xlfn.ISOWEEKNUM($R$2)),$D$1,$E$1)))) -> ON | Y9: =IF($A9="","",IF(COUNTA($K$2:$AO$2)-4,IF(OR(Y$4="Mon",Y$4="Tue"),$E$1,$D$1))) -> ON | Z9: =IF($A9="","",IF(COUNTA($K$2:$AO$2)-4,IF(OR(Z$4="Mon",Z$4="Tue"),$E$1,$D$1))) -> ON | AA9: =IF($A9="","",IF(COUNTA($K$2:$AO$2)-4,IF(OR(AA$4<>"Mon",AA$4<>"Tue"),IF(AND($G9="A",$H9="A",$J9="WK "&_xlfn.ISOWEEKNUM($Y$2)),$D$1,$E$1)))) -> ON | AB9: =IF($A9="","",IF(COUNTA($K$2:$AO$2)-4,IF(OR(AB$4<>"Mon",AB$4<>"Tue"),IF(AND($G9="B",$H9="B",$J9="WK "&_xlfn.ISOWEEKNUM($Y$2)),$D$1,$E$1)))) -> ON | AC9: =IF($A9="","",IF(COUNTA($K$2:$AO$2)-4,IF(OR(AC$4<>"Mon",AC$4<>"Tue"),IF(AND($G9="C",$H9="C",$J9="WK "&_xlfn.ISOWEEKNUM($Y$2)),$D$1,$E$1)))) -> ON | AD9: =IF($A9="","",IF(COUNTA($K$2:$AO$2)-4,IF(OR(AD$4<>"Mon",AD$4<>"Tue"),IF(AND($G9="D",$H9="D",$J9="WK "&_xlfn.ISOWEEKNUM($Y$2)),$D$1,$E$1)))) -> OFF | AF9: =IF($A9="","",IF(COUNTA($K$2:$AO$2)-4,IF(OR(AF$4="Mon",AF$4="Tue"),$E$1,$D$1))) -> ON | AG9: =IF($A9="","",IF(COUNTA($K$2:$AO$2)-4,IF(OR(AG$4="Mon",AG$4="Tue"),$E$1,$D$1))) -> ON | AH9: =IF($A9="","",IF(COUNTA($K$2:$AO$2)-4,IF(OR(AH$4<>"Mon",AH$4<>"Tue"),IF(AND($G9="A",$H9="A",$J9="WK "&_xlfn.ISOWEEKNUM($AF$2)),$D$1,$E$1)))) -> ON | AI9: =IF($A9="","",IF(COUNTA($K$2:$AO$2)-4,IF(OR(AI$4<>"Mon",AI$4<>"Tue"),IF(AND($G9="B",$H9="B",$J9="WK "&_xlfn.ISOWEEKNUM($AF$2)),$D$1,$E$1)))) -> ON | AJ9: =IF($A9="","",IF(COUNTA($K$2:$AO$2)-4,IF(OR(AJ$4<>"Mon",AJ$4<>"Tue"),IF(AND($G9="C",$H9="C",$J9="WK "&_xlfn.ISOWEEKNUM($AF$2)),$D$1,$E$1)))) -> ON | AK9: =IF($A9="","",IF(COUNTA($K$2:$AO$2)-4,IF(OR(AK$4<>"Mon",AK$4<>"Tue"),IF(AND($G9="D",$H9="D",$J9="WK "&_xlfn.ISOWEEKNUM($AF$2)),$D$1,$E$1)))) -> ON | AM9: =IF(COUNTA($K$2:$AO$2)-4,IF(OR(AM$4="Mon",AM$4="Tue"),$E$1,$D$1)) -> ON | AN9: =IF(COUNTA($K$2:$AO$2)-4,IF(OR(AN$4="Mon",AN$4="Tue"),$E$1,$D$1)) -> ON | AO9: =IF(COUNTA($K$2:$AO$2)-4,IF(OR(AO$4="Mon",AO$4="Tue",AO$4="Wed"),$E$1,$D$1)) -> ON
A10: =CHOOSE(RANDBETWEEN(1,5),"Lagos","Ogun","Ondo","Oyo","Ekiti") -> Ogun | B10: =CHOOSE(RANDBETWEEN(1,5),"A","B","C","D","E") -> B | C10: =CHOOSE(RANDBETWEEN(1,5),"A1","B1","C1","D1","E1") -> C1 | D10: Mini Truck | E10: =COUNTIF(K10:AO10, "ON") -> 25 | F10: =COUNTIF(K10:AO10, "OFF") -> 2 | G10: C | H10: C | I10: =IF($A10="","",IF(COUNTA($R$2:$W$2)=6,"WK "&_xlfn.ISOWEEKNUM($R$2))) -> WK 19 | J10: =IF($A10="","",IF(COUNTA($AF$2:$AK$2)=6,"WK "&_xlfn.ISOWEEKNUM($AF$2))) -> WK 21 | K10: =IF($A10="","",IF(COUNTA($K$2:$AO$2)-4,IF(OR(K$4="Mon",K$4="Tue"),$E$1,$D$1))) -> ON | L10: =IF($A10="","",IF(COUNTA($K$2:$AO$2)-4,IF(OR(L$4="Mon",L$4="Tue"),$E$1,$D$1))) -> ON | M10: =IF($A10="","",IF(COUNTA($K$2:$AO$2)-4,IF(OR(M$4<>"Mon",M$4<>"Tue"),IF(AND($G10="A",$H10="A",$I10="WK "&_xlfn.ISOWEEKNUM($K$2)),$D$1,$E$1)))) -> ON | N10: =IF($A10="","",IF(COUNTA($K$2:$AO$2)-4,IF(OR(N$4<>"Mon",N$4<>"Tue"),IF(AND($G10="B",$H10="B",$I10="WK "&_xlfn.ISOWEEKNUM($K$2)),$D$1,$E$1)))) -> ON | O10: =IF($A10="","",IF(COUNTA($K$2:$AO$2)-4,IF(OR(O$4<>"Mon",O$4<>"Tue"),IF(AND($G10="C",$H10="C",$I10="WK "&_xlfn.ISOWEEKNUM($K$2)),$D$1,$E$1)))) -> ON | P10: =IF($A10="","",IF(COUNTA($K$2:$AO$2)-4,IF(OR(P$4<>"Mon",P$4<>"Tue"),IF(AND($G10="D",$H10="D",$I10="WK "&_xlfn.ISOWEEKNUM($K$2)),$D$1,$E$1)))) -> ON | R10: =IF($A10="","",IF(COUNTA($K$2:$AO$2)-4,IF(OR(R$4="Mon",R$4="Tue"),$E$1,$D$1))) -> ON | S10: =IF($A10="","",IF(COUNTA($K$2:$AO$2)-4,IF(OR(S$4="Mon",S$4="Tue"),$E$1,$D$1))) -> ON | T10: =IF($A10="","",IF(COUNTA($K$2:$AO$2)-4,IF(OR(T$4<>"Mon",T$4<>"Tue"),IF(AND($G10="A",$H10="A",$I10="WK "&_xlfn.ISOWEEKNUM($R$2)),$D$1,$E$1)))) -> ON | U10: =IF($A10="","",IF(COUNTA($K$2:$AO$2)-4,IF(OR(U$4<>"Mon",U$4<>"Tue"),IF(AND($G10="B",$H10="B",$I10="WK "&_xlfn.ISOWEEKNUM($R$2)),$D$1,$E$1)))) -> ON | V10: =IF($A10="","",IF(COUNTA($K$2:$AO$2)-4,IF(OR(V$4<>"Mon",V$4<>"Tue"),IF(AND($G10="C",$H10="C",$I10="WK "&_xlfn.ISOWEEKNUM($R$2)),$D$1,$E$1)))) -> OFF | W10: =IF($A10="","",IF(COUNTA($K$2:$AO$2)-4,IF(OR(W$4<>"Mon",W$4<>"Tue"),IF(AND($G10="D",$H10="D",$I10="WK "&_xlfn.ISOWEEKNUM($R$2)),$D$1,$E$1)))) -> ON | Y10: =IF($A10="","",IF(COUNTA($K$2:$AO$2)-4,IF(OR(Y$4="Mon",Y$4="Tue"),$E$1,$D$1))) -> ON | Z10: =IF($A10="","",IF(COUNTA($K$2:$AO$2)-4,IF(OR(Z$4="Mon",Z$4="Tue"),$E$1,$D$1))) -> ON | AA10: =IF($A10="","",IF(COUNTA($K$2:$AO$2)-4,IF(OR(AA$4<>"Mon",AA$4<>"Tue"),IF(AND($G10="A",$H10="A",$J10="WK "&_xlfn.ISOWEEKNUM($Y$2)),$D$1,$E$1)))) -> ON | AB10: =IF($A10="","",IF(COUNTA($K$2:$AO$2)-4,IF(OR(AB$4<>"Mon",AB$4<>"Tue"),IF(AND($G10="B",$H10="B",$J10="WK "&_xlfn.ISOWEEKNUM($Y$2)),$D$1,$E$1)))) -> ON | AC10: =IF($A10="","",IF(COUNTA($K$2:$AO$2)-4,IF(OR(AC$4<>"Mon",AC$4<>"Tue"),IF(AND($G10="C",$H10="C",$J10="WK "&_xlfn.ISOWEEKNUM($Y$2)),$D$1,$E$1)))) -> ON | AD10: =IF($A10="","",IF(COUNTA($K$2:$AO$2)-4,IF(OR(AD$4<>"Mon",AD$4<>"Tue"),IF(AND($G10="D",$H10="D",$J10="WK "&_xlfn.ISOWEEKNUM($Y$2)),$D$1,$E$1)))) -> ON | AF10: =IF($A10="","",IF(COUNTA($K$2:$AO$2)-4,IF(OR(AF$4="Mon",AF$4="Tue"),$E$1,$D$1))) -> ON | AG10: =IF($A10="","",IF(COUNTA($K$2:$AO$2)-4,IF(OR(AG$4="Mon",AG$4="Tue"),$E$1,$D$1))) -> ON | AH10: =IF($A10="","",IF(COUNTA($K$2:$AO$2)-4,IF(OR(AH$4<>"Mon",AH$4<>"Tue"),IF(AND($G10="A",$H10="A",$J10="WK "&_xlfn.ISOWEEKNUM($AF$2)),$D$1,$E$1)))) -> ON | AI10: =IF($A10="","",IF(COUNTA($K$2:$AO$2)-4,IF(OR(AI$4<>"Mon",AI$4<>"Tue"),IF(AND($G10="B",$H10="B",$J10="WK "&_xlfn.ISOWEEKNUM($AF$2)),$D$1,$E$1)))) -> ON | AJ10: =IF($A10="","",IF(COUNTA($K$2:$AO$2)-4,IF(OR(AJ$4<>"Mon",AJ$4<>"Tue"),IF(AND($G10="C",$H10="C",$J10="WK "&_xlfn.ISOWEEKNUM($AF$2)),$D$1,$E$1)))) -> OFF | AK10: =IF($A10="","",IF(COUNTA($K$2:$AO$2)-4,IF(OR(AK$4<>"Mon",AK$4<>"Tue"),IF(AND($G10="D",$H10="D",$J10="WK "&_xlfn.ISOWEEKNUM($AF$2)),$D$1,$E$1)))) -> ON | AM10: =IF(COUNTA($K$2:$AO$2)-4,IF(OR(AM$4="Mon",AM$4="Tue"),$E$1,$D$1)) -> ON | AN10: =IF(COUNTA($K$2:$AO$2)-4,IF(OR(AN$4="Mon",AN$4="Tue"),$E$1,$D$1)) -> ON | AO10: =IF(COUNTA($K$2:$AO$2)-4,IF(OR(AO$4="Mon",AO$4="Tue",AO$4="Wed"),$E$1,$D$1)) -> ON
A11: =CHOOSE(RANDBETWEEN(1,5),"Lagos","Ogun","Ondo","Oyo","Ekiti") -> Ondo | B11: =CHOOSE(RANDBETWEEN(1,5),"A","B","C","D","E") -> E | C11: =CHOOSE(RANDBETWEEN(1,5),"A1","B1","C1","D1","E1") -> B1 | D11: Mini Truck | E11: =COUNTIF(K11:AO11, "ON") -> 25 | F11: =COUNTIF(K11:AO11, "OFF") -> 2 | G11: B | H11: B | I11: =IF($A11="","",IF(COUNTA($K$2:$P$2)=6,"WK "&_xlfn.ISOWEEKNUM($K$2))) -> WK 18 | J11: =IF($A11="","",IF(COUNTA($Y$2:$AD$2)=6,"WK "&_xlfn.ISOWEEKNUM($Y$2))) -> WK 20 | K11: =IF($A11="","",IF(COUNTA($K$2:$AO$2)-4,IF(OR(K$4="Mon",K$4="Tue"),$E$1,$D$1))) -> ON | L11: =IF($A11="","",IF(COUNTA($K$2:$AO$2)-4,IF(OR(L$4="Mon",L$4="Tue"),$E$1,$D$1))) -> ON | M11: =IF($A11="","",IF(COUNTA($K$2:$AO$2)-4,IF(OR(M$4<>"Mon",M$4<>"Tue"),IF(AND($G11="A",$H11="A",$I11="WK "&_xlfn.ISOWEEKNUM($K$2)),$D$1,$E$1)))) -> ON | N11: =IF($A11="","",IF(COUNTA($K$2:$AO$2)-4,IF(OR(N$4<>"Mon",N$4<>"Tue"),IF(AND($G11="B",$H11="B",$I11="WK "&_xlfn.ISOWEEKNUM($K$2)),$D$1,$E$1)))) -> OFF | O11: =IF($A11="","",IF(COUNTA($K$2:$AO$2)-4,IF(OR(O$4<>"Mon",O$4<>"Tue"),IF(AND($G11="C",$H11="C",$I11="WK "&_xlfn.ISOWEEKNUM($K$2)),$D$1,$E$1)))) -> ON | P11: =IF($A11="","",IF(COUNTA($K$2:$AO$2)-4,IF(OR(P$4<>"Mon",P$4<>"Tue"),IF(AND($G11="D",$H11="D",$I11="WK "&_xlfn.ISOWEEKNUM($K$2)),$D$1,$E$1)))) -> ON | R11: =IF($A11="","",IF(COUNTA($K$2:$AO$2)-4,IF(OR(R$4="Mon",R$4="Tue"),$E$1,$D$1))) -> ON | S11: =IF($A11="","",IF(COUNTA($K$2:$AO$2)-4,IF(OR(S$4="Mon",S$4="Tue"),$E$1,$D$1))) -> ON | T11: =IF($A11="","",IF(COUNTA($K$2:$AO$2)-4,IF(OR(T$4<>"Mon",T$4<>"Tue"),IF(AND($G11="A",$H11="A",$I11="WK "&_xlfn.ISOWEEKNUM($R$2)),$D$1,$E$1)))) -> ON | U11: =IF($A11="","",IF(COUNTA($K$2:$AO$2)-4,IF(OR(U$4<>"Mon",U$4<>"Tue"),IF(AND($G11="B",$H11="B",$I11="WK "&_xlfn.ISOWEEKNUM($R$2)),$D$1,$E$1)))) -> ON | V11: =IF($A11="","",IF(COUNTA($K$2:$AO$2)-4,IF(OR(V$4<>"Mon",V$4<>"Tue"),IF(AND($G11="C",$H11="C",$I11="WK "&_xlfn.ISOWEEKNUM($R$2)),$D$1,$E$1)))) -> ON | W11: =IF($A11="","",IF(COUNTA($K$2:$AO$2)-4,IF(OR(W$4<>"Mon",W$4<>"Tue"),IF(AND($G11="D",$H11="D",$I11="WK "&_xlfn.ISOWEEKNUM($R$2)),$D$1,$E$1)))) -> ON | Y11: =IF($A11="","",IF(COUNTA($K$2:$AO$2)-4,IF(OR(Y$4="Mon",Y$4="Tue"),$E$1,$D$1))) -> ON | Z11: =IF($A11="","",IF(COUNTA($K$2:$AO$2)-4,IF(OR(Z$4="Mon",Z$4="Tue"),$E$1,$D$1))) -> ON | AA11: =IF($A11="","",IF(COUNTA($K$2:$AO$2)-4,IF(OR(AA$4<>"Mon",AA$4<>"Tue"),IF(AND($G11="A",$H11="A",$J11="WK "&_xlfn.ISOWEEKNUM($Y$2)),$D$1,$E$1)))) -> ON | AB11: =IF($A11="","",IF(COUNTA($K$2:$AO$2)-4,IF(OR(AB$4<>"Mon",AB$4<>"Tue"),IF(AND($G11="B",$H11="B",$J11="WK "&_xlfn.ISOWEEKNUM($Y$2)),$D$1,$E$1)))) -> OFF | AC11: =IF($A11="","",IF(COUNTA($K$2:$AO$2)-4,IF(OR(AC$4<>"Mon",AC$4<>"Tue"),IF(AND($G11="C",$H11="C",$J11="WK "&_xlfn.ISOWEEKNUM($Y$2)),$D$1,$E$1)))) -> ON | AD11: =IF($A11="","",IF(COUNTA($K$2:$AO$2)-4,IF(OR(AD$4<>"Mon",AD$4<>"Tue"),IF(AND($G11="D",$H11="D",$J11="WK "&_xlfn.ISOWEEKNUM($Y$2)),$D$1,$E$1)))) -> ON | AF11: =IF($A11="","",IF(COUNTA($K$2:$AO$2)-4,IF(OR(AF$4="Mon",AF$4="Tue"),$E$1,$D$1))) -> ON | AG11: =IF($A11="","",IF(COUNTA($K$2:$AO$2)-4,IF(OR(AG$4="Mon",AG$4="Tue"),$E$1,$D$1))) -> ON | AH11: =IF($A11="","",IF(COUNTA($K$2:$AO$2)-4,IF(OR(AH$4<>"Mon",AH$4<>"Tue"),IF(AND($G11="A",$H11="A",$J11="WK "&_xlfn.ISOWEEKNUM($AF$2)),$D$1,$E$1)))) -> ON | AI11: =IF($A11="","",IF(COUNTA($K$2:$AO$2)-4,IF(OR(AI$4<>"Mon",AI$4<>"Tue"),IF(AND($G11="B",$H11="B",$J11="WK "&_xlfn.ISOWEEKNUM($AF$2)),$D$1,$E$1)))) -> ON | AJ11: =IF($A11="","",IF(COUNTA($K$2:$AO$2)-4,IF(OR(AJ$4<>"Mon",AJ$4<>"Tue"),IF(AND($G11="C",$H11="C",$J11="WK "&_xlfn.ISOWEEKNUM($AF$2)),$D$1,$E$1)))) -> ON | AK11: =IF($A11="","",IF(COUNTA($K$2:$AO$2)-4,IF(OR(AK$4<>"Mon",AK$4<>"Tue"),IF(AND($G11="D",$H11="D",$J11="WK "&_xlfn.ISOWEEKNUM($AF$2)),$D$1,$E$1)))) -> ON | AM11: =IF(COUNTA($K$2:$AO$2)-4,IF(OR(AM$4="Mon",AM$4="Tue"),$E$1,$D$1)) -> ON | AN11: =IF(COUNTA($K$2:$AO$2)-4,IF(OR(AN$4="Mon",AN$4="Tue"),$E$1,$D$1)) -> ON | AO11: =IF(COUNTA($K$2:$AO$2)-4,IF(OR(AO$4="Mon",AO$4="Tue",AO$4="Wed"),$E$1,$D$1)) -> ON
A12: =CHOOSE(RANDBETWEEN(1,5),"Lagos","Ogun","Ondo","Oyo","Ekiti") -> Lagos | B12: =CHOOSE(RANDBETWEEN(1,5),"A","B","C","D","E") -> D | C12: =CHOOSE(RANDBETWEEN(1,5),"A1","B1","C1","D1","E1") -> C1 | D12: Spare Driver | E12: =COUNTIF(K12:AO12, "ON") -> 25 | F12: =COUNTIF(K12:AO12, "OFF") -> 2 | G12: A | H12: A | I12: =IF($A12="","",IF(COUNTA($R$2:$W$2)=6,"WK "&_xlfn.ISOWEEKNUM($R$2))) -> WK 19 | J12: =IF($A12="","",IF(COUNTA($AF$2:$AK$2)=6,"WK "&_xlfn.ISOWEEKNUM($AF$2))) -> WK 21 | K12: =IF($A12="","",IF(COUNTA($K$2:$AO$2)-4,IF(OR(K$4="Mon",K$4="Tue"),$E$1,$D$1))) -> ON | L12: =IF($A12="","",IF(COUNTA($K$2:$AO$2)-4,IF(OR(L$4="Mon",L$4="Tue"),$E$1,$D$1))) -> ON | M12: =IF($A12="","",IF(COUNTA($K$2:$AO$2)-4,IF(OR(M$4<>"Mon",M$4<>"Tue"),IF(AND($G12="A",$H12="A",$I12="WK "&_xlfn.ISOWEEKNUM($K$2)),$D$1,$E$1)))) -> ON | N12: =IF($A12="","",IF(COUNTA($K$2:$AO$2)-4,IF(OR(N$4<>"Mon",N$4<>"Tue"),IF(AND($G12="B",$H12="B",$I12="WK "&_xlfn.ISOWEEKNUM($K$2)),$D$1,$E$1)))) -> ON | O12: =IF($A12="","",IF(COUNTA($K$2:$AO$2)-4,IF(OR(O$4<>"Mon",O$4<>"Tue"),IF(AND($G12="C",$H12="C",$I12="WK "&_xlfn.ISOWEEKNUM($K$2)),$D$1,$E$1)))) -> ON | P12: =IF($A12="","",IF(COUNTA($K$2:$AO$2)-4,IF(OR(P$4<>"Mon",P$4<>"Tue"),IF(AND($G12="D",$H12="D",$I12="WK "&_xlfn.ISOWEEKNUM($K$2)),$D$1,$E$1)))) -> ON | R12: =IF($A12="","",IF(COUNTA($K$2:$AO$2)-4,IF(OR(R$4="Mon",R$4="Tue"),$E$1,$D$1))) -> ON | S12: =IF($A12="","",IF(COUNTA($K$2:$AO$2)-4,IF(OR(S$4="Mon",S$4="Tue"),$E$1,$D$1))) -> ON | T12: =IF($A12="","",IF(COUNTA($K$2:$AO$2)-4,IF(OR(T$4<>"Mon",T$4<>"Tue"),IF(AND($G12="A",$H12="A",$I12="WK "&_xlfn.ISOWEEKNUM($R$2)),$D$1,$E$1)))) -> OFF | U12: =IF($A12="","",IF(COUNTA($K$2:$AO$2)-4,IF(OR(U$4<>"Mon",U$4<>"Tue"),IF(AND($G12="B",$H12="B",$I12="WK "&_xlfn.ISOWEEKNUM($R$2)),$D$1,$E$1)))) -> ON | V12: =IF($A12="","",IF(COUNTA($K$2:$AO$2)-4,IF(OR(V$4<>"Mon",V$4<>"Tue"),IF(AND($G12="C",$H12="C",$I12="WK "&_xlfn.ISOWEEKNUM($R$2)),$D$1,$E$1)))) -> ON | W12: =IF($A12="","",IF(COUNTA($K$2:$AO$2)-4,IF(OR(W$4<>"Mon",W$4<>"Tue"),IF(AND($G12="D",$H12="D",$I12="WK "&_xlfn.ISOWEEKNUM($R$2)),$D$1,$E$1)))) -> ON | Y12: =IF($A12="","",IF(COUNTA($K$2:$AO$2)-4,IF(OR(Y$4="Mon",Y$4="Tue"),$E$1,$D$1))) -> ON | Z12: =IF($A12="","",IF(COUNTA($K$2:$AO$2)-4,IF(OR(Z$4="Mon",Z$4="Tue"),$E$1,$D$1))) -> ON | AA12: =IF($A12="","",IF(COUNTA($K$2:$AO$2)-4,IF(OR(AA$4<>"Mon",AA$4<>"Tue"),IF(AND($G12="A",$H12="A",$J12="WK "&_xlfn.ISOWEEKNUM($Y$2)),$D$1,$E$1)))) -> ON | AB12: =IF($A12="","",IF(COUNTA($K$2:$AO$2)-4,IF(OR(AB$4<>"Mon",AB$4<>"Tue"),IF(AND($G12="B",$H12="B",$J12="WK "&_xlfn.ISOWEEKNUM($Y$2)),$D$1,$E$1)))) -> ON | AC12: =IF($A12="","",IF(COUNTA($K$2:$AO$2)-4,IF(OR(AC$4<>"Mon",AC$4<>"Tue"),IF(AND($G12="C",$H12="C",$J12="WK "&_xlfn.ISOWEEKNUM($Y$2)),$D$1,$E$1)))) -> ON | AD12: =IF($A12="","",IF(COUNTA($K$2:$AO$2)-4,IF(OR(AD$4<>"Mon",AD$4<>"Tue"),IF(AND($G12="D",$H12="D",$J12="WK "&_xlfn.ISOWEEKNUM($Y$2)),$D$1,$E$1)))) -> ON | AF12: =IF($A12="","",IF(COUNTA($K$2:$AO$2)-4,IF(OR(AF$4="Mon",AF$4="Tue"),$E$1,$D$1))) -> ON | AG12: =IF($A12="","",IF(COUNTA($K$2:$AO$2)-4,IF(OR(AG$4="Mon",AG$4="Tue"),$E$1,$D$1))) -> ON | AH12: =IF($A12="","",IF(COUNTA($K$2:$AO$2)-4,IF(OR(AH$4<>"Mon",AH$4<>"Tue"),IF(AND($G12="A",$H12="A",$J12="WK "&_xlfn.ISOWEEKNUM($AF$2)),$D$1,$E$1)))) -> OFF | AI12: =IF($A12="","",IF(COUNTA($K$2:$AO$2)-4,IF(OR(AI$4<>"Mon",AI$4<>"Tue"),IF(AND($G12="B",$H12="B",$J12="WK "&_xlfn.ISOWEEKNUM($AF$2)),$D$1,$E$1)))) -> ON | AJ12: =IF($A12="","",IF(COUNTA($K$2:$AO$2)-4,IF(OR(AJ$4<>"Mon",AJ$4<>"Tue"),IF(AND($G12="C",$H12="C",$J12="WK "&_xlfn.ISOWEEKNUM($AF$2)),$D$1,$E$1)))) -> ON | AK12: =IF($A12="","",IF(COUNTA($K$2:$AO$2)-4,IF(OR(AK$4<>"Mon",AK$4<>"Tue"),IF(AND($G12="D",$H12="D",$J12="WK "&_xlfn.ISOWEEKNUM($AF$2)),$D$1,$E$1)))) -> ON | AM12: =IF(COUNTA($K$2:$AO$2)-4,IF(OR(AM$4="Mon",AM$4="Tue"),$E$1,$D$1)) -> ON | AN12: =IF(COUNTA($K$2:$AO$2)-4,IF(OR(AN$4="Mon",AN$4="Tue"),$E$1,$D$1)) -> ON | AO12: =IF(COUNTA($K$2:$AO$2)-4,IF(OR(AO$4="Mon",AO$4="Tue",AO$4="Wed"),$E$1,$D$1)) -> ON
A13: =CHOOSE(RANDBETWEEN(1,5),"Lagos","Ogun","Ondo","Oyo","Ekiti") -> Oyo | B13: =CHOOSE(RANDBETWEEN(1,5),"A","B","C","D","E") -> C | C13: =CHOOSE(RANDBETWEEN(1,5),"A1","B1","C1","D1","E1") -> A1 | D13: Tricycle | E13: =COUNTIF(K13:AO13, "ON") -> 25 | F13: =COUNTIF(K13:AO13, "OFF") -> 2 | G13: {=Groups!$B$2:$B$5} -> A | H13: {=Groups!$B$2:$B$5} -> A | I13: =IF($A13="","",IF(COUNTA($K$2:$P$2)=6,"WK "&_xlfn.ISOWEEKNUM($K$2))) -> WK 18 | J13: =IF($A13="","",IF(COUNTA($Y$2:$AD$2)=6,"WK "&_xlfn.ISOWEEKNUM($Y$2))) -> WK 20 | K13: =IF($A13="","",IF(COUNTA($K$2:$AO$2)-4,IF(OR(K$4="Mon",K$4="Tue"),$E$1,$D$1))) -> ON | L13: =IF($A13="","",IF(COUNTA($K$2:$AO$2)-4,IF(OR(L$4="Mon",L$4="Tue"),$E$1,$D$1))) -> ON | M13: =IF($A13="","",IF(COUNTA($K$2:$AO$2)-4,IF(OR(M$4<>"Mon",M$4<>"Tue"),IF(AND($G13="A",$H13="A",$I13="WK "&_xlfn.ISOWEEKNUM($K$2)),$D$1,$E$1)))) -> OFF | N13: =IF($A13="","",IF(COUNTA($K$2:$AO$2)-4,IF(OR(N$4<>"Mon",N$4<>"Tue"),IF(AND($G13="B",$H13="B",$I13="WK "&_xlfn.ISOWEEKNUM($K$2)),$D$1,$E$1)))) -> ON | O13: =IF($A13="","",IF(COUNTA($K$2:$AO$2)-4,IF(OR(O$4<>"Mon",O$4<>"Tue"),IF(AND($G13="C",$H13="C",$I13="WK "&_xlfn.ISOWEEKNUM($K$2)),$D$1,$E$1)))) -> ON | P13: =IF($A13="","",IF(COUNTA($K$2:$AO$2)-4,IF(OR(P$4<>"Mon",P$4<>"Tue"),IF(AND($G13="D",$H13="D",$I13="WK "&_xlfn.ISOWEEKNUM($K$2)),$D$1,$E$1)))) -> ON | R13: =IF($A13="","",IF(COUNTA($K$2:$AO$2)-4,IF(OR(R$4="Mon",R$4="Tue"),$E$1,$D$1))) -> ON | S13: =IF($A13="","",IF(COUNTA($K$2:$AO$2)-4,IF(OR(S$4="Mon",S$4="Tue"),$E$1,$D$1))) -> ON | T13: =IF($A13="","",IF(COUNTA($K$2:$AO$2)-4,IF(OR(T$4<>"Mon",T$4<>"Tue"),IF(AND($G13="A",$H13="A",$I13="WK "&_xlfn.ISOWEEKNUM($R$2)),$D$1,$E$1)))) -> ON | U13: =IF($A13="","",IF(COUNTA($K$2:$AO$2)-4,IF(OR(U$4<>"Mon",U$4<>"Tue"),IF(AND($G13="B",$H13="B",$I13="WK "&_xlfn.ISOWEEKNUM($R$2)),$D$1,$E$1)))) -> ON | V13: =IF($A13="","",IF(COUNTA($K$2:$AO$2)-4,IF(OR(V$4<>"Mon",V$4<>"Tue"),IF(AND($G13="C",$H13="C",$I13="WK "&_xlfn.ISOWEEKNUM($R$2)),$D$1,$E$1)))) -> ON | W13: =IF($A13="","",IF(COUNTA($K$2:$AO$2)-4,IF(OR(W$4<>"Mon",W$4<>"Tue"),IF(AND($G13="D",$H13="D",$I13="WK "&_xlfn.ISOWEEKNUM($R$2)),$D$1,$E$1)))) -> ON | Y13: =IF($A13="","",IF(COUNTA($K$2:$AO$2)-4,IF(OR(Y$4="Mon",Y$4="Tue"),$E$1,$D$1))) -> ON | Z13: =IF($A13="","",IF(COUNTA($K$2:$AO$2)-4,IF(OR(Z$4="Mon",Z$4="Tue"),$E$1,$D$1))) -> ON | AA13: =IF($A13="","",IF(COUNTA($K$2:$AO$2)-4,IF(OR(AA$4<>"Mon",AA$4<>"Tue"),IF(AND($G13="A",$H13="A",$J13="WK "&_xlfn.ISOWEEKNUM($Y$2)),$D$1,$E$1)))) -> OFF | AB13: =IF($A13="","",IF(COUNTA($K$2:$AO$2)-4,IF(OR(AB$4<>"Mon",AB$4<>"Tue"),IF(AND($G13="B",$H13="B",$J13="WK "&_xlfn.ISOWEEKNUM($Y$2)),$D$1,$E$1)))) -> ON | AC13: =IF($A13="","",IF(COUNTA($K$2:$AO$2)-4,IF(OR(AC$4<>"Mon",AC$4<>"Tue"),IF(AND($G13="C",$H13="C",$J13="WK "&_xlfn.ISOWEEKNUM($Y$2)),$D$1,$E$1)))) -> ON | AD13: =IF($A13="","",IF(COUNTA($K$2:$AO$2)-4,IF(OR(AD$4<>"Mon",AD$4<>"Tue"),IF(AND($G13="D",$H13="D",$J13="WK "&_xlfn.ISOWEEKNUM($Y$2)),$D$1,$E$1)))) -> ON | AF13: =IF($A13="","",IF(COUNTA($K$2:$AO$2)-4,IF(OR(AF$4="Mon",AF$4="Tue"),$E$1,$D$1))) -> ON | AG13: =IF($A13="","",IF(COUNTA($K$2:$AO$2)-4,IF(OR(AG$4="Mon",AG$4="Tue"),$E$1,$D$1))) -> ON | AH13: =IF($A13="","",IF(COUNTA($K$2:$AO$2)-4,IF(OR(AH$4<>"Mon",AH$4<>"Tue"),IF(AND($G13="A",$H13="A",$J13="WK "&_xlfn.ISOWEEKNUM($AF$2)),$D$1,$E$1)))) -> ON | AI13: =IF($A13="","",IF(COUNTA($K$2:$AO$2)-4,IF(OR(AI$4<>"Mon",AI$4<>"Tue"),IF(AND($G13="B",$H13="B",$J13="WK "&_xlfn.ISOWEEKNUM($AF$2)),$D$1,$E$1)))) -> ON | AJ13: =IF($A13="","",IF(COUNTA($K$2:$AO$2)-4,IF(OR(AJ$4<>"Mon",AJ$4<>"Tue"),IF(AND($G13="C",$H13="C",$J13="WK "&_xlfn.ISOWEEKNUM($AF$2)),$D$1,$E$1)))) -> ON | AK13: =IF($A13="","",IF(COUNTA($K$2:$AO$2)-4,IF(OR(AK$4<>"Mon",AK$4<>"Tue"),IF(AND($G13="D",$H13="D",$J13="WK "&_xlfn.ISOWEEKNUM($AF$2)),$D$1,$E$1)))) -> ON | AM13: =IF(COUNTA($K$2:$AO$2)-4,IF(OR(AM$4="Mon",AM$4="Tue"),$E$1,$D$1)) -> ON | AN13: =IF(COUNTA($K$2:$AO$2)-4,IF(OR(AN$4="Mon",AN$4="Tue"),$E$1,$D$1)) -> ON | AO13: =IF(COUNTA($K$2:$AO$2)-4,IF(OR(AO$4="Mon",AO$4="Tue",AO$4="Wed"),$E$1,$D$1)) -> ON
A14: =CHOOSE(RANDBETWEEN(1,5),"Lagos","Ogun","Ondo","Oyo","Ekiti") -> Lagos | B14: =CHOOSE(RANDBETWEEN(1,5),"A","B","C","D","E") -> B | C14: =CHOOSE(RANDBETWEEN(1,5),"A1","B1","C1","D1","E1") -> D1 | D14: Tricycle | E14: =COUNTIF(K14:AO14, "ON") -> 25 | F14: =COUNTIF(K14:AO14, "OFF") -> 2 | G14: B | H14: B | I14: =IF($A14="","",IF(COUNTA($R$2:$W$2)=6,"WK "&_xlfn.ISOWEEKNUM($R$2))) -> WK 19 | J14: =IF($A14="","",IF(COUNTA($AF$2:$AK$2)=6,"WK "&_xlfn.ISOWEEKNUM($AF$2))) -> WK 21 | K14: =IF($A14="","",IF(COUNTA($K$2:$AO$2)-4,IF(OR(K$4="Mon",K$4="Tue"),$E$1,$D$1))) -> ON | L14: =IF($A14="","",IF(COUNTA($K$2:$AO$2)-4,IF(OR(L$4="Mon",L$4="Tue"),$E$1,$D$1))) -> ON | M14: =IF($A14="","",IF(COUNTA($K$2:$AO$2)-4,IF(OR(M$4<>"Mon",M$4<>"Tue"),IF(AND($G14="A",$H14="A",$I14="WK "&_xlfn.ISOWEEKNUM($K$2)),$D$1,$E$1)))) -> ON | N14: =IF($A14="","",IF(COUNTA($K$2:$AO$2)-4,IF(OR(N$4<>"Mon",N$4<>"Tue"),IF(AND($G14="B",$H14="B",$I14="WK "&_xlfn.ISOWEEKNUM($K$2)),$D$1,$E$1)))) -> ON | O14: =IF($A14="","",IF(COUNTA($K$2:$AO$2)-4,IF(OR(O$4<>"Mon",O$4<>"Tue"),IF(AND($G14="C",$H14="C",$I14="WK "&_xlfn.ISOWEEKNUM($K$2)),$D$1,$E$1)))) -> ON | P14: =IF($A14="","",IF(COUNTA($K$2:$AO$2)-4,IF(OR(P$4<>"Mon",P$4<>"Tue"),IF(AND($G14="D",$H14="D",$I14="WK "&_xlfn.ISOWEEKNUM($K$2)),$D$1,$E$1)))) -> ON | R14: =IF($A14="","",IF(COUNTA($K$2:$AO$2)-4,IF(OR(R$4="Mon",R$4="Tue"),$E$1,$D$1))) -> ON | S14: =IF($A14="","",IF(COUNTA($K$2:$AO$2)-4,IF(OR(S$4="Mon",S$4="Tue"),$E$1,$D$1))) -> ON | T14: =IF($A14="","",IF(COUNTA($K$2:$AO$2)-4,IF(OR(T$4<>"Mon",T$4<>"Tue"),IF(AND($G14="A",$H14="A",$I14="WK "&_xlfn.ISOWEEKNUM($R$2)),$D$1,$E$1)))) -> ON | U14: =IF($A14="","",IF(COUNTA($K$2:$AO$2)-4,IF(OR(U$4<>"Mon",U$4<>"Tue"),IF(AND($G14="B",$H14="B",$I14="WK "&_xlfn.ISOWEEKNUM($R$2)),$D$1,$E$1)))) -> OFF | V14: =IF($A14="","",IF(COUNTA($K$2:$AO$2)-4,IF(OR(V$4<>"Mon",V$4<>"Tue"),IF(AND($G14="C",$H14="C",$I14="WK "&_xlfn.ISOWEEKNUM($R$2)),$D$1,$E$1)))) -> ON | W14: =IF($A14="","",IF(COUNTA($K$2:$AO$2)-4,IF(OR(W$4<>"Mon",W$4<>"Tue"),IF(AND($G14="D",$H14="D",$I14="WK "&_xlfn.ISOWEEKNUM($R$2)),$D$1,$E$1)))) -> ON | Y14: =IF($A14="","",IF(COUNTA($K$2:$AO$2)-4,IF(OR(Y$4="Mon",Y$4="Tue"),$E$1,$D$1))) -> ON | Z14: =IF($A14="","",IF(COUNTA($K$2:$AO$2)-4,IF(OR(Z$4="Mon",Z$4="Tue"),$E$1,$D$1))) -> ON | AA14: =IF($A14="","",IF(COUNTA($K$2:$AO$2)-4,IF(OR(AA$4<>"Mon",AA$4<>"Tue"),IF(AND($G14="A",$H14="A",$J14="WK "&_xlfn.ISOWEEKNUM($Y$2)),$D$1,$E$1)))) -> ON | AB14: =IF($A14="","",IF(COUNTA($K$2:$AO$2)-4,IF(OR(AB$4<>"Mon",AB$4<>"Tue"),IF(AND($G14="B",$H14="B",$J14="WK "&_xlfn.ISOWEEKNUM($Y$2)),$D$1,$E$1)))) -> ON | AC14: =IF($A14="","",IF(COUNTA($K$2:$AO$2)-4,IF(OR(AC$4<>"Mon",AC$4<>"Tue"),IF(AND($G14="C",$H14="C",$J14="WK "&_xlfn.ISOWEEKNUM($Y$2)),$D$1,$E$1)))) -> ON | AD14: =IF($A14="","",IF(COUNTA($K$2:$AO$2)-4,IF(OR(AD$4<>"Mon",AD$4<>"Tue"),IF(AND($G14="D",$H14="D",$J14="WK "&_xlfn.ISOWEEKNUM($Y$2)),$D$1,$E$1)))) -> ON | AF14: =IF($A14="","",IF(COUNTA($K$2:$AO$2)-4,IF(OR(AF$4="Mon",AF$4="Tue"),$E$1,$D$1))) -> ON | AG14: =IF($A14="","",IF(COUNTA($K$2:$AO$2)-4,IF(OR(AG$4="Mon",AG$4="Tue"),$E$1,$D$1))) -> ON | AH14: =IF($A14="","",IF(COUNTA($K$2:$AO$2)-4,IF(OR(AH$4<>"Mon",AH$4<>"Tue"),IF(AND($G14="A",$H14="A",$J14="WK "&_xlfn.ISOWEEKNUM($AF$2)),$D$1,$E$1)))) -> ON | AI14: =IF($A14="","",IF(COUNTA($K$2:$AO$2)-4,IF(OR(AI$4<>"Mon",AI$4<>"Tue"),IF(AND($G14="B",$H14="B",$J14="WK "&_xlfn.ISOWEEKNUM($AF$2)),$D$1,$E$1)))) -> OFF | AJ14: =IF($A14="","",IF(COUNTA($K$2:$AO$2)-4,IF(OR(AJ$4<>"Mon",AJ$4<>"Tue"),IF(AND($G14="C",$H14="C",$J14="WK "&_xlfn.ISOWEEKNUM($AF$2)),$D$1,$E$1)))) -> ON | AK14: =IF($A14="","",IF(COUNTA($K$2:$AO$2)-4,IF(OR(AK$4<>"Mon",AK$4<>"Tue"),IF(AND($G14="D",$H14="D",$J14="WK "&_xlfn.ISOWEEKNUM($AF$2)),$D$1,$E$1)))) -> ON | AM14: =IF(COUNTA($K$2:$AO$2)-4,IF(OR(AM$4="Mon",AM$4="Tue"),$E$1,$D$1)) -> ON | AN14: =IF(COUNTA($K$2:$AO$2)-4,IF(OR(AN$4="Mon",AN$4="Tue"),$E$1,$D$1)) -> ON | AO14: =IF(COUNTA($K$2:$AO$2)-4,IF(OR(AO$4="Mon",AO$4="Tue",AO$4="Wed"),$E$1,$D$1)) -> ON
A15: =CHOOSE(RANDBETWEEN(1,5),"Lagos","Ogun","Ondo","Oyo","Ekiti") -> Ogun | B15: =CHOOSE(RANDBETWEEN(1,5),"A","B","C","D","E") -> B | C15: =CHOOSE(RANDBETWEEN(1,5),"A1","B1","C1","D1","E1") -> E1 | D15: Tricycle | E15: =COUNTIF(K15:AO15, "ON") -> 25 | F15: =COUNTIF(K15:AO15, "OFF") -> 2 | G15: C | H15: C | I15: =IF($A15="","",IF(COUNTA($K$2:$P$2)=6,"WK "&_xlfn.ISOWEEKNUM($K$2))) -> WK 18 | J15: =IF($A15="","",IF(COUNTA($Y$2:$AD$2)=6,"WK "&_xlfn.ISOWEEKNUM($Y$2))) -> WK 20 | K15: =IF($A15="","",IF(COUNTA($K$2:$AO$2)-4,IF(OR(K$4="Mon",K$4="Tue"),$E$1,$D$1))) -> ON | L15: =IF($A15="","",IF(COUNTA($K$2:$AO$2)-4,IF(OR(L$4="Mon",L$4="Tue"),$E$1,$D$1))) -> ON | M15: =IF($A15="","",IF(COUNTA($K$2:$AO$2)-4,IF(OR(M$4<>"Mon",M$4<>"Tue"),IF(AND($G15="A",$H15="A",$I15="WK "&_xlfn.ISOWEEKNUM($K$2)),$D$1,$E$1)))) -> ON | N15: =IF($A15="","",IF(COUNTA($K$2:$AO$2)-4,IF(OR(N$4<>"Mon",N$4<>"Tue"),IF(AND($G15="B",$H15="B",$I15="WK "&_xlfn.ISOWEEKNUM($K$2)),$D$1,$E$1)))) -> ON | O15: =IF($A15="","",IF(COUNTA($K$2:$AO$2)-4,IF(OR(O$4<>"Mon",O$4<>"Tue"),IF(AND($G15="C",$H15="C",$I15="WK "&_xlfn.ISOWEEKNUM($K$2)),$D$1,$E$1)))) -> OFF | P15: =IF($A15="","",IF(COUNTA($K$2:$AO$2)-4,IF(OR(P$4<>"Mon",P$4<>"Tue"),IF(AND($G15="D",$H15="D",$I15="WK "&_xlfn.ISOWEEKNUM($K$2)),$D$1,$E$1)))) -> ON | R15: =IF($A15="","",IF(COUNTA($K$2:$AO$2)-4,IF(OR(R$4="Mon",R$4="Tue"),$E$1,$D$1))) -> ON | S15: =IF($A15="","",IF(COUNTA($K$2:$AO$2)-4,IF(OR(S$4="Mon",S$4="Tue"),$E$1,$D$1))) -> ON | T15: =IF($A15="","",IF(COUNTA($K$2:$AO$2)-4,IF(OR(T$4<>"Mon",T$4<>"Tue"),IF(AND($G15="A",$H15="A",$I15="WK "&_xlfn.ISOWEEKNUM($R$2)),$D$1,$E$1)))) -> ON | U15: =IF($A15="","",IF(COUNTA($K$2:$AO$2)-4,IF(OR(U$4<>"Mon",U$4<>"Tue"),IF(AND($G15="B",$H15="B",$I15="WK "&_xlfn.ISOWEEKNUM($R$2)),$D$1,$E$1)))) -> ON | V15: =IF($A15="","",IF(COUNTA($K$2:$AO$2)-4,IF(OR(V$4<>"Mon",V$4<>"Tue"),IF(AND($G15="C",$H15="C",$I15="WK "&_xlfn.ISOWEEKNUM($R$2)),$D$1,$E$1)))) -> ON | W15: =IF($A15="","",IF(COUNTA($K$2:$AO$2)-4,IF(OR(W$4<>"Mon",W$4<>"Tue"),IF(AND($G15="D",$H15="D",$I15="WK "&_xlfn.ISOWEEKNUM($R$2)),$D$1,$E$1)))) -> ON | Y15: =IF($A15="","",IF(COUNTA($K$2:$AO$2)-4,IF(OR(Y$4="Mon",Y$4="Tue"),$E$1,$D$1))) -> ON | Z15: =IF($A15="","",IF(COUNTA($K$2:$AO$2)-4,IF(OR(Z$4="Mon",Z$4="Tue"),$E$1,$D$1))) -> ON | AA15: =IF($A15="","",IF(COUNTA($K$2:$AO$2)-4,IF(OR(AA$4<>"Mon",AA$4<>"Tue"),IF(AND($G15="A",$H15="A",$J15="WK "&_xlfn.ISOWEEKNUM($Y$2)),$D$1,$E$1)))) -> ON | AB15: =IF($A15="","",IF(COUNTA($K$2:$AO$2)-4,IF(OR(AB$4<>"Mon",AB$4<>"Tue"),IF(AND($G15="B",$H15="B",$J15="WK "&_xlfn.ISOWEEKNUM($Y$2)),$D$1,$E$1)))) -> ON | AC15: =IF($A15="","",IF(COUNTA($K$2:$AO$2)-4,IF(OR(AC$4<>"Mon",AC$4<>"Tue"),IF(AND($G15="C",$H15="C",$J15="WK "&_xlfn.ISOWEEKNUM($Y$2)),$D$1,$E$1)))) -> OFF | AD15: =IF($A15="","",IF(COUNTA($K$2:$AO$2)-4,IF(OR(AD$4<>"Mon",AD$4<>"Tue"),IF(AND($G15="D",$H15="D",$J15="WK "&_xlfn.ISOWEEKNUM($Y$2)),$D$1,$E$1)))) -> ON | AF15: =IF($A15="","",IF(COUNTA($K$2:$AO$2)-4,IF(OR(AF$4="Mon",AF$4="Tue"),$E$1,$D$1))) -> ON | AG15: =IF($A15="","",IF(COUNTA($K$2:$AO$2)-4,IF(OR(AG$4="Mon",AG$4="Tue"),$E$1,$D$1))) -> ON | AH15: =IF($A15="","",IF(COUNTA($K$2:$AO$2)-4,IF(OR(AH$4<>"Mon",AH$4<>"Tue"),IF(AND($G15="A",$H15="A",$J15="WK "&_xlfn.ISOWEEKNUM($AF$2)),$D$1,$E$1)))) -> ON | AI15: =IF($A15="","",IF(COUNTA($K$2:$AO$2)-4,IF(OR(AI$4<>"Mon",AI$4<>"Tue"),IF(AND($G15="B",$H15="B",$J15="WK "&_xlfn.ISOWEEKNUM($AF$2)),$D$1,$E$1)))) -> ON | AJ15: =IF($A15="","",IF(COUNTA($K$2:$AO$2)-4,IF(OR(AJ$4<>"Mon",AJ$4<>"Tue"),IF(AND($G15="C",$H15="C",$J15="WK "&_xlfn.ISOWEEKNUM($AF$2)),$D$1,$E$1)))) -> ON | AK15: =IF($A15="","",IF(COUNTA($K$2:$AO$2)-4,IF(OR(AK$4<>"Mon",AK$4<>"Tue"),IF(AND($G15="D",$H15="D",$J15="WK "&_xlfn.ISOWEEKNUM($AF$2)),$D$1,$E$1)))) -> ON | AM15: =IF(COUNTA($K$2:$AO$2)-4,IF(OR(AM$4="Mon",AM$4="Tue"),$E$1,$D$1)) -> ON | AN15: =IF(COUNTA($K$2:$AO$2)-4,IF(OR(AN$4="Mon",AN$4="Tue"),$E$1,$D$1)) -> ON | AO15: =IF(COUNTA($K$2:$AO$2)-4,IF(OR(AO$4="Mon",AO$4="Tue",AO$4="Wed"),$E$1,$D$1)) -> ON
A16: =CHOOSE(RANDBETWEEN(1,5),"Lagos","Ogun","Ondo","Oyo","Ekiti") -> Ondo | B16: =CHOOSE(RANDBETWEEN(1,5),"A","B","C","D","E") -> B | C16: =CHOOSE(RANDBETWEEN(1,5),"A1","B1","C1","D1","E1") -> C1 | D16: Van | E16: =COUNTIF(K16:AO16, "ON") -> 25 | F16: =COUNTIF(K16:AO16, "OFF") -> 2 | G16: D | H16: D | I16: =IF($A16="","",IF(COUNTA($R$2:$W$2)=6,"WK "&_xlfn.ISOWEEKNUM($R$2))) -> WK 19 | J16: =IF($A16="","",IF(COUNTA($AF$2:$AK$2)=6,"WK "&_xlfn.ISOWEEKNUM($AF$2))) -> WK 21 | K16: =IF($A16="","",IF(COUNTA($K$2:$AO$2)-4,IF(OR(K$4="Mon",K$4="Tue"),$E$1,$D$1))) -> ON | L16: =IF($A16="","",IF(COUNTA($K$2:$AO$2)-4,IF(OR(L$4="Mon",L$4="Tue"),$E$1,$D$1))) -> ON | M16: =IF($A16="","",IF(COUNTA($K$2:$AO$2)-4,IF(OR(M$4<>"Mon",M$4<>"Tue"),IF(AND($G16="A",$H16="A",$I16="WK "&_xlfn.ISOWEEKNUM($K$2)),$D$1,$E$1)))) -> ON | N16: =IF($A16="","",IF(COUNTA($K$2:$AO$2)-4,IF(OR(N$4<>"Mon",N$4<>"Tue"),IF(AND($G16="B",$H16="B",$I16="WK "&_xlfn.ISOWEEKNUM($K$2)),$D$1,$E$1)))) -> ON | O16: =IF($A16="","",IF(COUNTA($K$2:$AO$2)-4,IF(OR(O$4<>"Mon",O$4<>"Tue"),IF(AND($G16="C",$H16="C",$I16="WK "&_xlfn.ISOWEEKNUM($K$2)),$D$1,$E$1)))) -> ON | P16: =IF($A16="","",IF(COUNTA($K$2:$AO$2)-4,IF(OR(P$4<>"Mon",P$4<>"Tue"),IF(AND($G16="D",$H16="D",$I16="WK "&_xlfn.ISOWEEKNUM($K$2)),$D$1,$E$1)))) -> ON | R16: =IF($A16="","",IF(COUNTA($K$2:$AO$2)-4,IF(OR(R$4="Mon",R$4="Tue"),$E$1,$D$1))) -> ON | S16: =IF($A16="","",IF(COUNTA($K$2:$AO$2)-4,IF(OR(S$4="Mon",S$4="Tue"),$E$1,$D$1))) -> ON | T16: =IF($A16="","",IF(COUNTA($K$2:$AO$2)-4,IF(OR(T$4<>"Mon",T$4<>"Tue"),IF(AND($G16="A",$H16="A",$I16="WK "&_xlfn.ISOWEEKNUM($R$2)),$D$1,$E$1)))) -> ON | U16: =IF($A16="","",IF(COUNTA($K$2:$AO$2)-4,IF(OR(U$4<>"Mon",U$4<>"Tue"),IF(AND($G16="B",$H16="B",$I16="WK "&_xlfn.ISOWEEKNUM($R$2)),$D$1,$E$1)))) -> ON | V16: =IF($A16="","",IF(COUNTA($K$2:$AO$2)-4,IF(OR(V$4<>"Mon",V$4<>"Tue"),IF(AND($G16="C",$H16="C",$I16="WK "&_xlfn.ISOWEEKNUM($R$2)),$D$1,$E$1)))) -> ON | W16: =IF($A16="","",IF(COUNTA($K$2:$AO$2)-4,IF(OR(W$4<>"Mon",W$4<>"Tue"),IF(AND($G16="D",$H16="D",$I16="WK "&_xlfn.ISOWEEKNUM($R$2)),$D$1,$E$1)))) -> OFF | Y16: =IF($A16="","",IF(COUNTA($K$2:$AO$2)-4,IF(OR(Y$4="Mon",Y$4="Tue"),$E$1,$D$1))) -> ON | Z16: =IF($A16="","",IF(COUNTA($K$2:$AO$2)-4,IF(OR(Z$4="Mon",Z$4="Tue"),$E$1,$D$1))) -> ON | AA16: =IF($A16="","",IF(COUNTA($K$2:$AO$2)-4,IF(OR(AA$4<>"Mon",AA$4<>"Tue"),IF(AND($G16="A",$H16="A",$J16="WK "&_xlfn.ISOWEEKNUM($Y$2)),$D$1,$E$1)))) -> ON | AB16: =IF($A16="","",IF(COUNTA($K$2:$AO$2)-4,IF(OR(AB$4<>"Mon",AB$4<>"Tue"),IF(AND($G16="B",$H16="B",$J16="WK "&_xlfn.ISOWEEKNUM($Y$2)),$D$1,$E$1)))) -> ON | AC16: =IF($A16="","",IF(COUNTA($K$2:$AO$2)-4,IF(OR(AC$4<>"Mon",AC$4<>"Tue"),IF(AND($G16="C",$H16="C",$J16="WK "&_xlfn.ISOWEEKNUM($Y$2)),$D$1,$E$1)))) -> ON | AD16: =IF($A16="","",IF(COUNTA($K$2:$AO$2)-4,IF(OR(AD$4<>"Mon",AD$4<>"Tue"),IF(AND($G16="D",$H16="D",$J16="WK "&_xlfn.ISOWEEKNUM($Y$2)),$D$1,$E$1)))) -> ON | AF16: =IF($A16="","",IF(COUNTA($K$2:$AO$2)-4,IF(OR(AF$4="Mon",AF$4="Tue"),$E$1,$D$1))) -> ON | AG16: =IF($A16="","",IF(COUNTA($K$2:$AO$2)-4,IF(OR(AG$4="Mon",AG$4="Tue"),$E$1,$D$1))) -> ON | AH16: =IF($A16="","",IF(COUNTA($K$2:$AO$2)-4,IF(OR(AH$4<>"Mon",AH$4<>"Tue"),IF(AND($G16="A",$H16="A",$J16="WK "&_xlfn.ISOWEEKNUM($AF$2)),$D$1,$E$1)))) -> ON | AI16: =IF($A16="","",IF(COUNTA($K$2:$AO$2)-4,IF(OR(AI$4<>"Mon",AI$4<>"Tue"),IF(AND($G16="B",$H16="B",$J16="WK "&_xlfn.ISOWEEKNUM($AF$2)),$D$1,$E$1)))) -> ON | AJ16: =IF($A16="","",IF(COUNTA($K$2:$AO$2)-4,IF(OR(AJ$4<>"Mon",AJ$4<>"Tue"),IF(AND($G16="C",$H16="C",$J16="WK "&_xlfn.ISOWEEKNUM($AF$2)),$D$1,$E$1)))) -> ON | AK16: =IF($A16="","",IF(COUNTA($K$2:$AO$2)-4,IF(OR(AK$4<>"Mon",AK$4<>"Tue"),IF(AND($G16="D",$H16="D",$J16="WK "&_xlfn.ISOWEEKNUM($AF$2)),$D$1,$E$1)))) -> OFF | AM16: =IF(COUNTA($K$2:$AO$2)-4,IF(OR(AM$4="Mon",AM$4="Tue"),$E$1,$D$1)) -> ON | AN16: =IF(COUNTA($K$2:$AO$2)-4,IF(OR(AN$4="Mon",AN$4="Tue"),$E$1,$D$1)) -> ON | AO16: =IF(COUNTA($K$2:$AO$2)-4,IF(OR(AO$4="Mon",AO$4="Tue",AO$4="Wed"),$E$1,$D$1)) -> ON
A17: =CHOOSE(RANDBETWEEN(1,5),"Lagos","Ogun","Ondo","Oyo","Ekiti") -> Ekiti | B17: =CHOOSE(RANDBETWEEN(1,5),"A","B","C","D","E") -> C | C17: =CHOOSE(RANDBETWEEN(1,5),"A1","B1","C1","D1","E1") -> A1 | D17: Van | E17: =COUNTIF(K17:AO17, "ON") -> 25 | F17: =COUNTIF(K17:AO17, "OFF") -> 2 | G17: {=IF($G$5:$G$8={"A";"B";"C";"D"},{"D";"C";"B";"A"},{"A";"B";"C";"D"})} -> D | H17: {=IF($H$5:$H$8={"A";"B";"C";"D"},{"D";"C";"B";"A"},{"A";"B";"C";"D"})} -> D | I17: =IF($A17="","",IF(COUNTA($K$2:$P$2)=6,"WK "&_xlfn.ISOWEEKNUM($K$2))) -> WK 18 | J17: =IF($A17="","",IF(COUNTA($Y$2:$AD$2)=6,"WK "&_xlfn.ISOWEEKNUM($Y$2))) -> WK 20 | K17: =IF($A17="","",IF(COUNTA($K$2:$AO$2)-4,IF(OR(K$4="Mon",K$4="Tue"),$E$1,$D$1))) -> ON | L17: =IF($A17="","",IF(COUNTA($K$2:$AO$2)-4,IF(OR(L$4="Mon",L$4="Tue"),$E$1,$D$1))) -> ON | M17: =IF($A17="","",IF(COUNTA($K$2:$AO$2)-4,IF(OR(M$4<>"Mon",M$4<>"Tue"),IF(AND($G17="A",$H17="A",$I17="WK "&_xlfn.ISOWEEKNUM($K$2)),$D$1,$E$1)))) -> ON | N17: =IF($A17="","",IF(COUNTA($K$2:$AO$2)-4,IF(OR(N$4<>"Mon",N$4<>"Tue"),IF(AND($G17="B",$H17="B",$I17="WK "&_xlfn.ISOWEEKNUM($K$2)),$D$1,$E$1)))) -> ON | O17: =IF($A17="","",IF(COUNTA($K$2:$AO$2)-4,IF(OR(O$4<>"Mon",O$4<>"Tue"),IF(AND($G17="C",$H17="C",$I17="WK "&_xlfn.ISOWEEKNUM($K$2)),$D$1,$E$1)))) -> ON | P17: =IF($A17="","",IF(COUNTA($K$2:$AO$2)-4,IF(OR(P$4<>"Mon",P$4<>"Tue"),IF(AND($G17="D",$H17="D",$I17="WK "&_xlfn.ISOWEEKNUM($K$2)),$D$1,$E$1)))) -> OFF | R17: =IF($A17="","",IF(COUNTA($K$2:$AO$2)-4,IF(OR(R$4="Mon",R$4="Tue"),$E$1,$D$1))) -> ON | S17: =IF($A17="","",IF(COUNTA($K$2:$AO$2)-4,IF(OR(S$4="Mon",S$4="Tue"),$E$1,$D$1))) -> ON | T17: =IF($A17="","",IF(COUNTA($K$2:$AO$2)-4,IF(OR(T$4<>"Mon",T$4<>"Tue"),IF(AND($G17="A",$H17="A",$I17="WK "&_xlfn.ISOWEEKNUM($R$2)),$D$1,$E$1)))) -> ON | U17: =IF($A17="","",IF(COUNTA($K$2:$AO$2)-4,IF(OR(U$4<>"Mon",U$4<>"Tue"),IF(AND($G17="B",$H17="B",$I17="WK "&_xlfn.ISOWEEKNUM($R$2)),$D$1,$E$1)))) -> ON | V17: =IF($A17="","",IF(COUNTA($K$2:$AO$2)-4,IF(OR(V$4<>"Mon",V$4<>"Tue"),IF(AND($G17="C",$H17="C",$I17="WK "&_xlfn.ISOWEEKNUM($R$2)),$D$1,$E$1)))) -> ON | W17: =IF($A17="","",IF(COUNTA($K$2:$AO$2)-4,IF(OR(W$4<>"Mon",W$4<>"Tue"),IF(AND($G17="D",$H17="D",$I17="WK "&_xlfn.ISOWEEKNUM($R$2)),$D$1,$E$1)))) -> ON | Y17: =IF($A17="","",IF(COUNTA($K$2:$AO$2)-4,IF(OR(Y$4="Mon",Y$4="Tue"),$E$1,$D$1))) -> ON | Z17: =IF($A17="","",IF(COUNTA($K$2:$AO$2)-4,IF(OR(Z$4="Mon",Z$4="Tue"),$E$1,$D$1))) -> ON | AA17: =IF($A17="","",IF(COUNTA($K$2:$AO$2)-4,IF(OR(AA$4<>"Mon",AA$4<>"Tue"),IF(AND($G17="A",$H17="A",$J17="WK "&_xlfn.ISOWEEKNUM($Y$2)),$D$1,$E$1)))) -> ON | AB17: =IF($A17="","",IF(COUNTA($K$2:$AO$2)-4,IF(OR(AB$4<>"Mon",AB$4<>"Tue"),IF(AND($G17="B",$H17="B",$J17="WK "&_xlfn.ISOWEEKNUM($Y$2)),$D$1,$E$1)))) -> ON | AC17: =IF($A17="","",IF(COUNTA($K$2:$AO$2)-4,IF(OR(AC$4<>"Mon",AC$4<>"Tue"),IF(AND($G17="C",$H17="C",$J17="WK "&_xlfn.ISOWEEKNUM($Y$2)),$D$1,$E$1)))) -> ON | AD17: =IF($A17="","",IF(COUNTA($K$2:$AO$2)-4,IF(OR(AD$4<>"Mon",AD$4<>"Tue"),IF(AND($G17="D",$H17="D",$J17="WK "&_xlfn.ISOWEEKNUM($Y$2)),$D$1,$E$1)))) -> OFF | AF17: =IF($A17="","",IF(COUNTA($K$2:$AO$2)-4,IF(OR(AF$4="Mon",AF$4="Tue"),$E$1,$D$1))) -> ON | AG17: =IF($A17="","",IF(COUNTA($K$2:$AO$2)-4,IF(OR(AG$4="Mon",AG$4="Tue"),$E$1,$D$1))) -> ON | AH17: =IF($A17="","",IF(COUNTA($K$2:$AO$2)-4,IF(OR(AH$4<>"Mon",AH$4<>"Tue"),IF(AND($G17="A",$H17="A",$J17="WK "&_xlfn.ISOWEEKNUM($AF$2)),$D$1,$E$1)))) -> ON | AI17: =IF($A17="","",IF(COUNTA($K$2:$AO$2)-4,IF(OR(AI$4<>"Mon",AI$4<>"Tue"),IF(AND($G17="B",$H17="B",$J17="WK "&_xlfn.ISOWEEKNUM($AF$2)),$D$1,$E$1)))) -> ON | AJ17: =IF($A17="","",IF(COUNTA($K$2:$AO$2)-4,IF(OR(AJ$4<>"Mon",AJ$4<>"Tue"),IF(AND($G17="C",$H17="C",$J17="WK "&_xlfn.ISOWEEKNUM($AF$2)),$D$1,$E$1)))) -> ON | AK17: =IF($A17="","",IF(COUNTA($K$2:$AO$2)-4,IF(OR(AK$4<>"Mon",AK$4<>"Tue"),IF(AND($G17="D",$H17="D",$J17="WK "&_xlfn.ISOWEEKNUM($AF$2)),$D$1,$E$1)))) -> ON | AM17: =IF(COUNTA($K$2:$AO$2)-4,IF(OR(AM$4="Mon",AM$4="Tue"),$E$1,$D$1)) -> ON | AN17: =IF(COUNTA($K$2:$AO$2)-4,IF(OR(AN$4="Mon",AN$4="Tue"),$E$1,$D$1)) -> ON | AO17: =IF(COUNTA($K$2:$AO$2)-4,IF(OR(AO$4="Mon",AO$4="Tue",AO$4="Wed"),$E$1,$D$1)) -> ON
A18: =CHOOSE(RANDBETWEEN(1,5),"Lagos","Ogun","Ondo","Oyo","Ekiti") -> Ogun | B18: =CHOOSE(RANDBETWEEN(1,5),"A","B","C","D","E") -> D | C18: =CHOOSE(RANDBETWEEN(1,5),"A1","B1","C1","D1","E1") -> B1 | D18: Van | E18: =COUNTIF(K18:AO18, "ON") -> 25 | F18: =COUNTIF(K18:AO18, "OFF") -> 2 | G18: C | H18: C | I18: =IF($A18="","",IF(COUNTA($R$2:$W$2)=6,"WK "&_xlfn.ISOWEEKNUM($R$2))) -> WK 19 | J18: =IF($A18="","",IF(COUNTA($AF$2:$AK$2)=6,"WK "&_xlfn.ISOWEEKNUM($AF$2))) -> WK 21 | K18: =IF($A18="","",IF(COUNTA($K$2:$AO$2)-4,IF(OR(K$4="Mon",K$4="Tue"),$E$1,$D$1))) -> ON | L18: =IF($A18="","",IF(COUNTA($K$2:$AO$2)-4,IF(OR(L$4="Mon",L$4="Tue"),$E$1,$D$1))) -> ON | M18: =IF($A18="","",IF(COUNTA($K$2:$AO$2)-4,IF(OR(M$4<>"Mon",M$4<>"Tue"),IF(AND($G18="A",$H18="A",$I18="WK "&_xlfn.ISOWEEKNUM($K$2)),$D$1,$E$1)))) -> ON | N18: =IF($A18="","",IF(COUNTA($K$2:$AO$2)-4,IF(OR(N$4<>"Mon",N$4<>"Tue"),IF(AND($G18="B",$H18="B",$I18="WK "&_xlfn.ISOWEEKNUM($K$2)),$D$1,$E$1)))) -> ON | O18: =IF($A18="","",IF(COUNTA($K$2:$AO$2)-4,IF(OR(O$4<>"Mon",O$4<>"Tue"),IF(AND($G18="C",$H18="C",$I18="WK "&_xlfn.ISOWEEKNUM($K$2)),$D$1,$E$1)))) -> ON | P18: =IF($A18="","",IF(COUNTA($K$2:$AO$2)-4,IF(OR(P$4<>"Mon",P$4<>"Tue"),IF(AND($G18="D",$H18="D",$I18="WK "&_xlfn.ISOWEEKNUM($K$2)),$D$1,$E$1)))) -> ON | R18: =IF($A18="","",IF(COUNTA($K$2:$AO$2)-4,IF(OR(R$4="Mon",R$4="Tue"),$E$1,$D$1))) -> ON | S18: =IF($A18="","",IF(COUNTA($K$2:$AO$2)-4,IF(OR(S$4="Mon",S$4="Tue"),$E$1,$D$1))) -> ON | T18: =IF($A18="","",IF(COUNTA($K$2:$AO$2)-4,IF(OR(T$4<>"Mon",T$4<>"Tue"),IF(AND($G18="A",$H18="A",$I18="WK "&_xlfn.ISOWEEKNUM($R$2)),$D$1,$E$1)))) -> ON | U18: =IF($A18="","",IF(COUNTA($K$2:$AO$2)-4,IF(OR(U$4<>"Mon",U$4<>"Tue"),IF(AND($G18="B",$H18="B",$I18="WK "&_xlfn.ISOWEEKNUM($R$2)),$D$1,$E$1)))) -> ON | V18: =IF($A18="","",IF(COUNTA($K$2:$AO$2)-4,IF(OR(V$4<>"Mon",V$4<>"Tue"),IF(AND($G18="C",$H18="C",$I18="WK "&_xlfn.ISOWEEKNUM($R$2)),$D$1,$E$1)))) -> OFF | W18: =IF($A18="","",IF(COUNTA($K$2:$AO$2)-4,IF(OR(W$4<>"Mon",W$4<>"Tue"),IF(AND($G18="D",$H18="D",$I18="WK "&_xlfn.ISOWEEKNUM($R$2)),$D$1,$E$1)))) -> ON | Y18: =IF($A18="","",IF(COUNTA($K$2:$AO$2)-4,IF(OR(Y$4="Mon",Y$4="Tue"),$E$1,$D$1))) -> ON | Z18: =IF($A18="","",IF(COUNTA($K$2:$AO$2)-4,IF(OR(Z$4="Mon",Z$4="Tue"),$E$1,$D$1))) -> ON | AA18: =IF($A18="","",IF(COUNTA($K$2:$AO$2)-4,IF(OR(AA$4<>"Mon",AA$4<>"Tue"),IF(AND($G18="A",$H18="A",$J18="WK "&_xlfn.ISOWEEKNUM($Y$2)),$D$1,$E$1)))) -> ON | AB18: =IF($A18="","",IF(COUNTA($K$2:$AO$2)-4,IF(OR(AB$4<>"Mon",AB$4<>"Tue"),IF(AND($G18="B",$H18="B",$J18="WK "&_xlfn.ISOWEEKNUM($Y$2)),$D$1,$E$1)))) -> ON | AC18: =IF($A18="","",IF(COUNTA($K$2:$AO$2)-4,IF(OR(AC$4<>"Mon",AC$4<>"Tue"),IF(AND($G18="C",$H18="C",$J18="WK "&_xlfn.ISOWEEKNUM($Y$2)),$D$1,$E$1)))) -> ON | AD18: =IF($A18="","",IF(COUNTA($K$2:$AO$2)-4,IF(OR(AD$4<>"Mon",AD$4<>"Tue"),IF(AND($G18="D",$H18="D",$J18="WK "&_xlfn.ISOWEEKNUM($Y$2)),$D$1,$E$1)))) -> ON | AF18: =IF($A18="","",IF(COUNTA($K$2:$AO$2)-4,IF(OR(AF$4="Mon",AF$4="Tue"),$E$1,$D$1))) -> ON | AG18: =IF($A18="","",IF(COUNTA($K$2:$AO$2)-4,IF(OR(AG$4="Mon",AG$4="Tue"),$E$1,$D$1))) -> ON | AH18: =IF($A18="","",IF(COUNTA($K$2:$AO$2)-4,IF(OR(AH$4<>"Mon",AH$4<>"Tue"),IF(AND($G18="A",$H18="A",$J18="WK "&_xlfn.ISOWEEKNUM($AF$2)),$D$1,$E$1)))) -> ON | AI18: =IF($A18="","",IF(COUNTA($K$2:$AO$2)-4,IF(OR(AI$4<>"Mon",AI$4<>"Tue"),IF(AND($G18="B",$H18="B",$J18="WK "&_xlfn.ISOWEEKNUM($AF$2)),$D$1,$E$1)))) -> ON | AJ18: =IF($A18="","",IF(COUNTA($K$2:$AO$2)-4,IF(OR(AJ$4<>"Mon",AJ$4<>"Tue"),IF(AND($G18="C",$H18="C",$J18="WK "&_xlfn.ISOWEEKNUM($AF$2)),$D$1,$E$1)))) -> OFF | AK18: =IF($A18="","",IF(COUNTA($K$2:$AO$2)-4,IF(OR(AK$4<>"Mon",AK$4<>"Tue"),IF(AND($G18="D",$H18="D",$J18="WK "&_xlfn.ISOWEEKNUM($AF$2)),$D$1,$E$1)))) -> ON | AM18: =IF(COUNTA($K$2:$AO$2)-4,IF(OR(AM$4="Mon",AM$4="Tue"),$E$1,$D$1)) -> ON | AN18: =IF(COUNTA($K$2:$AO$2)-4,IF(OR(AN$4="Mon",AN$4="Tue"),$E$1,$D$1)) -> ON | AO18: =IF(COUNTA($K$2:$AO$2)-4,IF(OR(AO$4="Mon",AO$4="Tue",AO$4="Wed"),$E$1,$D$1)) -> ON
